Workbook

Sheet Spreadsheet_guide
A1: Info about PsyTEC constructs for expression in Psy:
A2: HA tag adds ~1.23kDa to each protein
A3: Opening sequence of all constructs (upstream of promoter):
A4: GCGGCCGCAGTTACCTGGAGTAGTGTTGGC
A5: HA tag sequence (preceeded by 2 amino acid linker, followed by stop, after the final amino acid):
A6: TACCCTTACGATGTTCCTGATTACGCA
A7: Ending sequence (after HA tag finishes):
A8: CAGCCCGCCTAATGAGCGGGCTTTTTTTTGCGCGTAGCAGATGATGACAAGTCGCGGCCGC
A10: Sheet_name | B10: Sheet_description
A11: PsyTEC_alleles | B11: Promoter & nucleotide/amino acid sequence information for all 529 PsyTEC v2.0 constructs; information about immunoblot expression and Arabidopsis Col-0 ETI for both PtoDC3000 and PmaES4326. See Laflamme et al. 2020 and Martel et al. 2022
A12: DC3000 Identical alleles | B12: Promoter & nucleotide/amino acid sequence information for all PtoDC3000 alleles
A13: PsyTEC 96-well plate guide | B13: How PsyTEC (in DH5 alpha on pBBR1MCS-2) is arrayed across six 96-well plates for high-throughput tri-parental matings (stored in Desveaux lab -80). See Martel et al. 2022
A14: Discontinued after v1 | B14: Effector constructs which exist in DH5 alpha (in both pDONR207 and pBBR1MCS-2) and have been mated into PtoDC3000 - but which are no longer considered part of PsyTEC as of v2.0.
A15: Resynthesized&disc. effectors | B15: Effector constructs which exist in DH5 alpha (in both pDONR207 and pBBR1MCS-2) and have been mated into PtoDC3000 - but which were resynthesized due to an incorrect start codon being identified or to include a chaperone.
A16: Never synthesized | B16: This sheet remembers construct #584 (HopB2l), the only PsyTEC construct which was never synthesized due to particular difficulty in the synthesis.
A17: Hrps + helpers | B17: Non-effector constructs which exist in DH5 alpha (in both pDONR207 and pBBR1MCS-2) and have been mated into PtoDC3000 - but which are no longer considered part of PsyTEC as of v2.0.
A25: Notes
A26: 329, HopAX1d | B26: Originally marked as no expression in PtoDC3000 but is ETI-eliciting in same strain. Updated spreadsheet to show as expressing for data manipulation

Sheet PsyTEC_alleles
A1: PsyTEC_ID | B1: Effector | C1: Family | D1: Subfamily | E1: Frequency | F1: Representative_effector | G1: Chaperone | H1: Strain | I1: Contig | J1: hrp_box | K1: CDS | L1: Construct_sequence | M1: Barcode | N1: Construct_length_nuc | O1: CDS_length_nuc | P1: Protein_sequence | Q1: Protein_length_aa | R1: Predicted_MW_kDa | S1: Immunoblot_DC3000 | T1: At_Col0_ETI_DC3000 | U1: Immunoblot_ES4326 | V1: At_Col0_ETI_ES4326 | W1: Cognate_NLR | X1: Notes
A2: 1 | B2: HopX1a | C2: HopX | D2: HopX1 | E2: 102 | F2: PgyICMP10448_HopX1a_1 | J2: GGAACCAACTCGCACGCAAAACCACACA | K2: ATGAGAATTCACAGTGCTGGTCACAGCCTGCCCGCGCCAGGCCCTAGCGTGGAAACCACTGAAAAGGCTGTTCAATCATCATCGGCCCAGAACCCCGCTTCTTGCAGTTCACAAACAGAACGTCCTGAAGCCGGTTCGACTCAAGTGCGACCGAACTACCCTTACTCATCAGTCAAGACACGCTTGCCACCCGTTTCTTCCACAGGGCAGGCCATTTCTGACACGCCATCTTCATTGCCCGGTTACCTGCTGTTACGTCGGCTCGACCGACGTCCACTGGATGAAGACAGTATCAAGGCTCTGGTTCCGGCAGACGAAGCGTTGCGTGAAGCACGCCGCGCGTTGCCCTTCGGCAGGGGCAACATTGATGTGGATGCACAACGTACCCACCTGCAAAGCGGCGCTCGCGCAGTCGCTGCAAAGCGCTTGAGAAAAGATGCCGAGCGCGCTGGCCATGAGCCGATGCCCGAGAATGATGAGATGAACTGGCATGTTCTTGTCGCCATGTCAGGGCAGGTGTTTGGCGCTGGCAACTGTGGCGAACATGCTCGTATAGCAAGCTTCGCTTACGGGGCCCTGGCTCAGGAAAGCGGGCGTAGTCCCCGCGAAAAGATTCATTTGGCCGAGCAGCCCGGAAAAGATCACGTCTGGGCTGAAACGGATAATTCCAGCGCTGGCTCTTCGCCCATCGTCATGGACCCGTGGTCTAACGGCGCAGCCATTTTGGCGGAGGACAGCCGGTTTGCCAAAGATCGCAGTGCGGTAGAGCGAACATATTCATTCACCCTTGCAATGGCAGCTGAAGCCGGCAAGGTTGCGCGTGAAACCGCCGAGAACGTTCTGACCCACACGACAAGCCGTCTGCAGAAACGTCTTGCTGATCAGTTGCCGAACGTCTCACCGCTTGAAGGAGGCCGCTATCAGCCGGAAAAGTCGGTGCTTGATGAGGCGTTCGCCCGACGAGTGAGCGACAAGTTGAATAGTGACGATCCACGGCGTGCGTTGCAGATGGAAATTGAAGCTGTTGGTGTTGCAATGTCGCTGGGTGCCGAAGGCGTCAAGACGGTCGCCCGACAGGCGCCAAAGGTGGTCAGGCAAGCCAGAAGCGTCGCGTCGTCTAAAGGCATGCCTCCACGAAGATAA | L2: GCGGCCGCAGTTACCTGGAGTAGTGTTGGCGTTCGCCTGAGTGGATATCTGTCTGGAACCAACTCGCACGCAAAACCACACAGTTGCCATCCTTCACCACTTGGATGGCAACCATGAGAATTCACAGTGCTGGTCACAGCCTGCCCGCGCCAGGCCCTAGCGTGGAAACCACTGAAAAGGCTGTTCAATCATCATCGGCCCAGAACCCCGCTTCTTGCAGTTCACAAACAGAACGTCCTGAAGCCGGTTCGACTCAAGTGCGACCGAACTACCCTTACTCATCAGTCAAGACACGCTTGCCACCCGTTTCTTCCACAGGGCAGGCCATTTCTGACACGCCATCTTCATTGCCCGGTTACCTGCTGTTACGTCGGCTCGACCGACGTCCACTGGATGAAGACAGTATCAAGGCTCTGGTTCCGGCAGACGAAGCGTTGCGTGAAGCACGCCGCGCGTTGCCCTTCGGCAGGGGCAACATTGATGTGGATGCACAACGTACCCACCTGCAAAGCGGCGCTCGCGCAGTCGCTGCAAAGCGCTTGAGAAAAGATGCCGAGCGCGCTGGCCATGAGCCGATGCCCGAGAATGATGAGATGAACTGGCATGTTCTTGTCGCCATGTCAGGGCAGGTGTTTGGCGCTGGCAACTGTGGCGAACATGCTCGTATAGCAAGCTTCGCTTACGGGGCCCTGGCTCAGGAAAGCGGGCGTAGTCCCCGCGAAAAGATTCATTTGGCCGAGCAGCCCGGAAAAGATCACGTCTGGGCTGAAACGGATAATTCCAGCGCTGGCTCTTCGCCCATCGTCATGGACCCGTGGTCTAACGGCGCAGCCATTTTGGCGGAGGACAGCCGGTTTGCCAAAGATCGCAGTGCGGTAGAGCGAACATATTCATTCACCCTTGCAATGGCAGCTGAAGCCGGCAAGGTTGCGCGTGAAACCGCCGAGAACGTTCTGACCCACACGACAAGCCGTCTGCAGAAACGTCTTGCTGATCAGTTGCCGAACGTCTCACCGCTTGAAGGAGGCCGCTATCAGCCGGAAAAGTCGGTGCTTGATGAGGCGTTCGCCCGACGAGTGAGCGACAAGTTGAATAGTGACGATCCACGGCGTGCGTTGCAGATGGAAATTGAAGCTGTTGGTGTTGCAATGTCGCTGGGTGCCGAAGGCGTCAAGACGGTCGCCCGACAGGCGCCAAAGGTGGTCAGGCAAGCCAGAAGCGTCGCGTCGTCTAAAGGCATGCCTCCACGAAGAGGCGCATACCCTTACGATGTTCCTGATTACGCATAACAAAGCACCAGCCCGCCTAATGAGCGGGCTTTTTTTTGCGCGTAGCAGATGATGACAAGTCGCGGCCGC | M2: CAAAGCAC | N2: =LEN(L2) -> 1358 | O2: =LEN(K2) -> 1143 | P2: MRIHSAGHSLPAPGPSVETTEKAVQSSSAQNPASCSSQTERPEAGSTQVRPNYPYSSVKTRLPPVSSTGQAISDTPSSLPGYLLLRRLDRRPLDEDSIKALVPADEALREARRALPFGRGNIDVDAQRTHLQSGARAVAAKRLRKDAERAGHEPMPENDEMNWHVLVAMSGQVFGAGNCGEHARIASFAYGALAQESGRSPREKIHLAEQPGKDHVWAETDNSSAGSSPIVMDPWSNGAAILAEDSRFAKDRSAVERTYSFTLAMAAEAGKVARETAENVLTHTTSRLQKRLADQLPNVSPLEGGRYQPEKSVLDEAFARRVSDKLNSDDPRRALQMEIEAVGVAMSLGAEGVKTVARQAPKVVRQARSVASSKGMPPRR* | Q2: =(O2-3)/3 -> 380 | R2: 41.00891 | S2: 1 | T2: 0 | U2: 1 | V2: 0
A3: 2 | B3: HopX1c | C3: HopX | D3: HopX1 | E3: 69 | F3: PmpFTRS_U7_HopX1c_1 | J3: GGAACTGACCCGGCCCAAATGACGACATA | K3: ATGAAAATACATAACTCTGGCCTAACCCCACCTTTGCCGGGCATTTCGAATGGAAACGTTGGAAAAGCGGCGCAATCATCAATGACTCAACCGCAGAGCCAACAAGGCTCTCATAGCTTGCCACCAGAAAGCTCTGAGACTCGCCCTGATAGAGCGCGTGCGAACTATCCATATTCATCAGTACAAACACGGTTGCCGCCCGTTGCGTCTGCTGGGAAACCGCTGCCTGATACACCATCTTCTTTGCCCGGCTACTTACTGTTGCGAAGGCTGGACCATCGCCCTGTGGATCAGGAAGGTACCAAAAGTCTGATCCCGGCAGACAAGGCTGTGGCTGAAGCGCGCCGTGCATTGCCCTTTGGAAGAGGCAATATTGATGTGGATGCGCAACTTTCCAATTTGGAAAGTGGAGCCCGCACCCTTGCAGCAAGGTGCTTGAGAAAAGATGCCGAGGCCGCCGGTCATGAGCCGATGCCTGCGAATGAGCCGATGAACTGGCATGTTCTTGTTGCGATGTCAGGACAGGTGTTCGGCGCGGGCAACTGTGGCGAACATGCTCGTATAGCGAGCTTCGCCTATGGAGCTTTGGCCCAGGAAAACGGACGATCTGAAGATGAAAACATCTACTTGGCTGCATCGACTGAGGAGGATCATGTGTGGGCTGAAACCGACGAATCCCAGTCTGGCACCTCAACGATTGTCATGGATCCGTGGTCAAATGGTTCAGCCATATTTGCGGAGGACAGTAGGTTTGCGAAAAATCGAAATGCTGTAGAGCGTACGGATACGTTTAATCTTTCAACCGCAGCTGAAGCGGGCAAAATTACGCGTGAGACAGCCGAGAAGGCTTTGACGCAGGTCACAACCCGATTGCAGAAACGCCTGGCGGATCAGCAGGAGCAAGTCTCGCCCATCAAAAGTGGTCGCTATCGACCAGAAAAATCGGTACTTGATGATGCATTTGTCCGCAGAGTGAGCGACAAGTTGACCTCCACTGATTTGCGGCGTGCACTACAGGTAGACATTGAAGCGGTCGGAGTCGCAATGTCGCTCGGCACCAAGGGCGTCAAGGAAGCTACTCGACAAGCCCGACCTTTGGTTGAGCTTGCAGTGAAGGTCGCCTCTCCTCAAGGCTTGGCGAGACGAGATGTCTGA | L3: GCGGCCGCAGTTACCTGGAGTAGTGTTGGCCATAGATTAGGGAACTTGCTTGGGGGGAACTGACCCGGCCCAAATGACGACATAGCGAGCATGATGAAAGTATTTAATTCGTTGAGATAAAATGAAAATACATAACTCTGGCCTAACCCCACCTTTGCCGGGCATTTCGAATGGAAACGTTGGAAAAGCGGCGCAATCATCAATGACTCAACCGCAGAGCCAACAAGGCTCTCATAGCTTGCCACCAGAAAGCTCTGAGACTCGCCCTGATAGAGCGCGTGCGAACTATCCATATTCATCAGTACAAACACGGTTGCCGCCCGTTGCGTCTGCTGGGAAACCGCTGCCTGATACACCATCTTCTTTGCCCGGCTACTTACTGTTGCGAAGGCTGGACCATCGCCCTGTGGATCAGGAAGGTACCAAAAGTCTGATCCCGGCAGACAAGGCTGTGGCTGAAGCGCGCCGTGCATTGCCCTTTGGAAGAGGCAATATTGATGTGGATGCGCAACTTTCCAATTTGGAAAGTGGAGCCCGCACCCTTGCAGCAAGGTGCTTGAGAAAAGATGCCGAGGCCGCCGGTCATGAGCCGATGCCTGCGAATGAGCCGATGAACTGGCATGTTCTTGTTGCGATGTCAGGACAGGTGTTCGGCGCGGGCAACTGTGGCGAACATGCTCGTATAGCGAGCTTCGCCTATGGAGCTTTGGCCCAGGAAAACGGACGATCTGAAGATGAAAACATCTACTTGGCTGCATCGACTGAGGAGGATCATGTGTGGGCTGAAACCGACGAATCCCAGTCTGGCACCTCAACGATTGTCATGGACCCGTGGTCAAATGGTTCAGCCATATTTGCGGAGGACAGTAGGTTTGCGAAAAATCGAAATGCTGTAGAGCGTACGGATACGTTTAATCTTTCAACCGCAGCTGAAGCGGGCAAAATTACGCGTGAGACAGCCGAGAAGGCTTTGACGCAGGTCACAACCCGATTGCAGAAACGCCTGGCGGATCAGCAGGAGCAAGTCTCGCCCATCAAAAGTGGTCGCTATCGACCAGAAAAATCGGTACTTGATGATGCATTTGTCCGCAGAGTGAGCGACAAGTTGACCTCCACTGATTTGCGGCGTGCACTACAGGTAGACATTGAAGCGGTCGGAGTCGCAATGTCGCTCGGCACCAAGGGCGTCAAGGAAGCTACTCGACAAGCCCGACCTTTGGTTGAGCTTGCAGTGAAGGTCGCCTCTCCTCAAGGCTTGGCGAGACGAGATGTCGGCGCATACCCTTACGATGTTCCTGATTACGCATGACGTACACGCAGCCCGCCTAATGAGCGGGCTTTTTTTTGCGCGTAGCAGATGATGACAAGTCGCGGCCGC | M3: CGTACACG | N3: =LEN(L3) -> 1378 | O3: =LEN(K3) -> 1155 | P3: MKIHNSGLTPPLPGISNGNVGKAAQSSMTQPQSQQGSHSLPPESSETRPDRARANYPYSSVQTRLPPVASAGKPLPDTPSSLPGYLLLRRLDHRPVDQEGTKSLIPADKAVAEARRALPFGRGNIDVDAQLSNLESGARTLAARCLRKDAEAAGHEPMPANEPMNWHVLVAMSGQVFGAGNCGEHARIASFAYGALAQENGRSEDENIYLAASTEEDHVWAETDESQSGTSTIVMDPWSNGSAIFAEDSRFAKNRNAVERTDTFNLSTAAEAGKITRETAEKALTQVTTRLQKRLADQQEQVSPIKSGRYRPEKSVLDDAFVRRVSDKLTSTDLRRALQVDIEAVGVAMSLGTKGVKEATRQARPLVELAVKVASPQGLARRDV* | Q3: =(O3-3)/3 -> 384 | R3: 41.41028 | S3: 1 | T3: 0 | U3: 1 | V3: 0
A4: 3 | B4: HopX1b | C4: HopX | D4: HopX1 | E4: 72 | F4: PgcICMP4323_HopX1b_1 | J4: GGAACCAACCCGGACCAGGTGACGACTTA | K4: ATGAAAATCCATAACGCTGGCGTAACCGGTCCTTTGCCGAGCATCTCGAATGAAGGCGCTGGAAAGGCGGCGCAATCATCATCGACTCAACCGCAGAGCCAGCCAGAATCTCATGGTCCAACACCGGAAAGCTCTGAGGCTCACCCTGCCAGGGTGCGTACGAACTACCCTTACTCATCAGTAAAAACAAGATTGCCGCCCGTTGCTTCTGCAGGGAAAGCGCTGCCTGAAGCACTGTCTTCACTGCCCGGCTACTTACTGTTGCGAAGGCTGGACCATCGCCCTGTGGACCAAGAAGGTATTAACAGTCTGATCCCGGCAGACAAGGCTGTGACTGAAGCGCGCCATGCATTGCCCTTTGGAAGAGGCAATATTGATGTGGATGCGCAACTTACCAATCAGGAAAGTAGAGCCCGCACTGTTGCAGCACGGCGTTTGAGAAAAGATGCTGAGGCCGCCGGTCATGAGCCGATGCCTGCGAATGCGCCGATGAACTGGCATGTTCTTGTTGCGATGTCAGGCCAGGTGTTCGGCGCGGGCAACTGTGGCGAGCATGCGCATATAGCAAGCTTCGCCTATGGAGCTTTGGCCCAGGAAAACGGACGGCCTGAAGATGAAAACATTCACTTGGCTGCATCCACTGAGGAAGATCATGTGTGGGCTGAAACCGACGAATCCCGGTCTGGCACCTCAACGATTGTTATGGACCCGTGGTCAAACGGTCCCGCCATATTTGCGGAAGACAGCAGGTTTGCGAAAAATCGAAATGCTGTAGAGCGTACAGATACGTTTAAACTTTCAACCGCCGCCGAAGCGGGCAACATTACGCGTGAAATAGCGGAGAAGGCTTTGACGCAGGCCACACCCCGTCTGCAGCAGCGTCTGGCGGATCAACAGGCGCAAGTCTTGCCCATCAGAAGTGGTCGCTATCGACAAGAACAATCGGTACTTGATGATGCGTTTGTCCGCAGAGTGAGCGGCAAGTTAACCACTCCCAATCCGCAGCATGCACTGCAGGTGGAAATGGAGGCGGTCGGCGTCGCAATGTCGCTCGGTGCCAAGGACGTCAAGGAAGTTACTCGAAAAGCCCGACCTCTGGTTGAGCTAGCAGAGAAAGTCGCCTCTCCCCAAGGCTTGTCGCGACGAGATGTTTGA | L4: GCGGCCGCAGTTACCTGGAGTAGTGTTGGCCCTGGATGAGCGGACCTGCTTGGGAGGAACCAACCCGGACCAGGTGACGACTTAGCGAACATGGTTAAAGTATTCGATTCGTTGAGGGTGAAATGAAAATCCATAACGCTGGCGTAACCGGTCCTTTGCCGAGCATCTCGAATGAAGGCGCTGGAAAGGCGGCGCAATCATCATCGACTCAACCGCAGAGCCAGCCAGAATCTCATGGTCCAACACCGGAAAGCTCTGAGGCTCACCCTGCCAGGGTGCGTACGAACTACCCTTACTCATCAGTAAAAACAAGATTGCCGCCCGTTGCTTCTGCAGGGAAAGCGCTGCCTGAAGCACTGTCTTCACTGCCCGGCTACTTACTGTTGCGAAGGCTGGACCATCGCCCTGTGGACCAAGAAGGTATTAACAGTCTGATCCCGGCAGACAAGGCTGTGACTGAAGCGCGCCATGCATTGCCCTTTGGAAGAGGCAATATTGATGTGGATGCGCAACTTACCAATCAGGAAAGTAGAGCCCGCACTGTTGCAGCACGGCGTTTGAGAAAAGATGCTGAGGCCGCCGGTCATGAGCCGATGCCTGCGAATGCGCCGATGAACTGGCATGTTCTTGTTGCGATGTCAGGCCAGGTGTTCGGCGCGGGCAACTGTGGCGAGCATGCGCATATAGCAAGCTTCGCCTATGGAGCTTTGGCCCAGGAAAACGGACGGCCTGAAGATGAAAACATTCACTTGGCTGCATCCACTGAGGAAGATCATGTGTGGGCTGAAACCGACGAATCCCGGTCTGGCACCTCAACGATTGTTATGGACCCGTGGTCAAACGGTCCCGCCATATTTGCGGAAGACAGCAGGTTTGCGAAAAATCGAAATGCTGTAGAGCGTACAGATACGTTTAAACTTTCAACCGCCGCCGAAGCGGGCAACATTACGCGTGAAATAGCGGAGAAGGCTTTGACGCAGGCCACACCCCGTCTGCAGCAGCGTCTGGCGGATCAACAGGCGCAAGTCTTGCCCATCAGAAGTGGTCGCTATCGACAAGAACAATCGGTACTTGATGATGCGTTTGTCCGCAGAGTGAGCGGCAAGTTAACCACTCCCAATCCGCAGCATGCACTGCAGGTGGAAATGGAGGCGGTCGGCGTCGCAATGTCGCTCGGTGCCAAGGACGTCAAGGAAGTTACTCGAAAAGCCCGACCTCTGGTTGAGCTAGCAGAGAAAGTCGCCTCTCCCCAAGGCTTGTCGCGACGAGATGTTGGCGCATACCCTTACGATGTTCCTGATTACGCATGAGATGAGCCCAGCCCGCCTAATGAGCGGGCTTTTTTTTGCGCGTAGCAGATGATGACAAGTCGCGGCCGC | M4: GATGAGCC | N4: =LEN(L4) -> 1379 | O4: =LEN(K4) -> 1155 | P4: MKIHNAGVTGPLPSISNEGAGKAAQSSSTQPQSQPESHGPTPESSEAHPARVRTNYPYSSVKTRLPPVASAGKALPEALSSLPGYLLLRRLDHRPVDQEGINSLIPADKAVTEARHALPFGRGNIDVDAQLTNQESRARTVAARRLRKDAEAAGHEPMPANAPMNWHVLVAMSGQVFGAGNCGEHAHIASFAYGALAQENGRPEDENIHLAASTEEDHVWAETDESRSGTSTIVMDPWSNGPAIFAEDSRFAKNRNAVERTDTFKLSTAAEAGNITREIAEKALTQATPRLQQRLADQQAQVLPIRSGRYRQEQSVLDDAFVRRVSGKLTTPNPQHALQVEMEAVGVAMSLGAKDVKEVTRKARPLVELAEKVASPQGLSRRDV* | Q4: =(O4-3)/3 -> 384 | R4: 41.40122 | S4: 1 | T4: 0 | U4: 1 | V4: 0
A5: 4 | B5: HopX1i | C5: HopX | D5: HopX1 | E5: 5 | F5: PdpICMP13052_HopX1i_1 | J5: GGAACCAACTCGCACCTTCAGCCACACA | K5: ATGAAAATACATAACGCTGGCCCAAGCATTCCGATGCCCGCTCCATCGATTGAGAGCGCTGGCAAGACTGCGCAATCATCATTGGCTCAACCGCAGAGCCAACGAGCCACCCCCGTCTCGCCATCAGAGACTTCTGATGCCCGTCCGTCCAGTGTGCGTACGAACTACCCTTATTCATCAGTCAAAACACGGTTGCCTCCCGTTGCGTCTGCAGGGCAGCCACTGTCCGGGATGCCGTCTTCATTACCCGGCTACTTGCTGTTACGTCGGCTTGACCATCGTCCACTGGATCAAGACGGTATCAAAGGTTTGATTCCAGCAGATGAAGCGGTGGGTGAAGCACGTCGCGCGTTGCCTTTCGGCAGGGGCAATATCGACGTGGATGCGCAACGCTCCAACTTGGAAAGCGGAGCCCGCACACTCGCGGCTAGGCGTTTGAGAAAAGATGCCGAGGCCGCGGGTCACGAACCAATGCCTGCAAATGAAGATATGAACTGGCATGTTCTTGTTGCGATGTCAGGACAGGTTTTTGGCGCAGGTAACTGCGGGGAACATGCCCGCATAGCGAGTTTCGCCTACGGTGCACTGGCTCAGGAAAAAGGGCGGAACGCCGATGAGACTATTCATTTGGCTGCGCAACGCGGTAAAGACCACGTCTGGGCTGAAACGGACAATTCAAGCGCTGGATCTTCACCGGTTGTCATGGATCCGTGGTCGAACGGTCCTGCCATTTTTGCGGAGGATAGTCGGTTTGCCAAAGATCGAAGTACGGTAGAACGAACGGATTCCTTCACGCTTGCAACTGCTGCTGAAGCAGGCAAGATCACGCGAGAGACGGCCGAGAATGCTTTGACACAGGCGACCAGCCGTTTGCAGAAACGTCTTGCTGATCAGAAAACGCAAGTCTCGCCGCTTGCAGGAGGGCGCTATCGGCAAGAAAATTCGGTGCTTGATGACGCGTTCGCCCGACGGGCAAGTGGCAAGTTGAGCAACAAGGATCCGCGGCATGCATTACAGGTGGAAATCGAGGCGGCCGCAGTTGCAATGTCGCTGGGCGCCCAAGGCGTAAAAGCGGTTGCGGAACAGGCCCGGACGGTAGTTGAACAAGCCAGGAAGGTCGCATCTCCCCAAGGCACGCCTCAGCGAGATACGTGA | L5: GCGGCCGCAGTTACCTGGAGTAGTGTTGGCAATGGCGATCTCGATCATTTTTTCTGGAACCAACTCGCACCTTCAGCCACACAGTTGCCATCCCTCACTCTCGGATGGCAACTCACCATGAAAATACATAACGCTGGCCCAAGCATTCCGATGCCCGCTCCATCGATTGAGAGCGCTGGCAAGACTGCGCAATCATCATTGGCTCAACCGCAGAGCCAACGAGCCACCCCCGTCTCGCCATCAGAGACTTCTGATGCCCGTCCGTCCAGTGTGCGTACGAACTACCCTTATTCATCAGTCAAAACACGGTTGCCTCCCGTTGCGTCTGCAGGGCAGCCACTGTCCGGGATGCCGTCTTCATTACCCGGCTACTTGCTGTTACGTCGGCTTGACCATCGTCCACTGGATCAAGACGGTATCAAAGGTTTGATTCCAGCAGATGAAGCGGTGGGTGAAGCACGTCGCGCGTTGCCTTTCGGCAGGGGCAATATCGACGTGGATGCGCAACGCTCCAACTTGGAAAGCGGAGCCCGCACACTCGCGGCTAGGCGTTTGAGAAAAGATGCCGAGGCCGCGGGTCACGAACCAATGCCTGCAAATGAAGATATGAACTGGCATGTTCTTGTTGCGATGTCAGGACAGGTTTTTGGCGCAGGTAACTGCGGGGAACATGCCCGCATAGCGAGTTTCGCCTACGGTGCACTGGCTCAGGAAAAAGGGCGGAACGCCGATGAGACTATTCATTTGGCTGCGCAACGCGGTAAAGACCACGTCTGGGCTGAAACGGACAATTCAAGCGCTGGATCTTCACCGGTTGTCATGGACCCGTGGTCGAACGGTCCTGCCATTTTTGCGGAGGATAGTCGGTTTGCCAAAGATCGAAGTACGGTAGAACGAACGGATTCCTTCACGCTTGCAACTGCTGCTGAAGCAGGCAAGATCACGCGAGAGACGGCCGAGAATGCTTTGACACAGGCGACCAGCCGTTTGCAGAAACGTCTTGCTGATCAGAAAACGCAAGTCTCGCCGCTTGCAGGAGGGCGCTATCGGCAAGAAAATTCGGTGCTTGATGACGCGTTCGCCCGACGGGCAAGTGGCAAGTTGAGCAACAAGGACCCGCGGCATGCATTACAGGTGGAAATCGAGGCAGCCGCAGTTGCAATGTCGCTGGGCGCCCAAGGCGTAAAAGCGGTTGCGGAACAGGCCCGGACGGTAGTTGAACAAGCCAGGAAGGTCGCATCTCCCCAAGGCACGCCTCAGCGAGATACGGGCGCATACCCTTACGATGTTCCTGATTACGCATGACTCGAATCCAGCCCGCCTAATGAGCGGGCTTTTTTTTGCGCGTAGCAGATGATGACAAGTCGCGGCCGC | M5: CTCGAATC | N5: =LEN(L5) -> 1374 | O5: =LEN(K5) -> 1155 | P5: MKIHNAGPSIPMPAPSIESAGKTAQSSLAQPQSQRATPVSPSETSDARPSSVRTNYPYSSVKTRLPPVASAGQPLSGMPSSLPGYLLLRRLDHRPLDQDGIKGLIPADEAVGEARRALPFGRGNIDVDAQRSNLESGARTLAARRLRKDAEAAGHEPMPANEDMNWHVLVAMSGQVFGAGNCGEHARIASFAYGALAQEKGRNADETIHLAAQRGKDHVWAETDNSSAGSSPVVMDPWSNGPAIFAEDSRFAKDRSTVERTDSFTLATAAEAGKITRETAENALTQATSRLQKRLADQKTQVSPLAGGRYRQENSVLDDAFARRASGKLSNKDPRHALQVEIEAAAVAMSLGAQGVKAVAEQARTVVEQARKVASPQGTPQRDT* | Q5: =(O5-3)/3 -> 384 | R5: 40.86556 | S5: 1 | T5: 1 | U5: 1 | V5: 1 | W5: ZAR1
A6: 5 | B6: HopX1e | C6: HopX | D6: HopX1 | E6: 13 | F6: PpiH6E5_HopX1e_1 | J6: GGAACCAACTTGCGCGCAAAACCACACA | K6: ATGAGAATTCACAGTTCTGGTCATGGCATCTGCGCACCAGTGTCCTCTGCAGAAACCGTTGAAAAGGCCGTGCAATCATCGGCCCAAGCGCAGAATGAAGCGTCTCACAGCGGTCCATCAGAACATCCTGAATCCCGCTCCTGTCAGGCACGCCCGAACTACCCTTATTCGTCAGTCAAAACACGGTTACCCCCTGTTGCGTCTGCAGGGCAGTCGTCGTCTGAGACACCCTCTTCATTGCCTGGCTACCTGCTGTTACGTCGGCTTGATCGTCGTCAGCTGGACCAGGACGCAATAAAGGGGCTTATTCCTGCTGATGAAGCAGTGGGCGAAGCGCGCCGCGCGTTGCCCTTCGGCAGGGGCAATATTGATGTGGATGCGCAACGCACCCATCTGCAAAGCGGAGCCCGCACACTCGCGGCAAGGCGCCTGAGAAAAGACGCCGAGGCGGCGGGTCATGAGCCGATGCCCGAGAACGAAGACATGAACTGGCATGTGCTGGTTGCCATGTCGGGTCAGGTGTTCGGTGCGGGCAACTGTGGCGAACATGCGCGTATAGCGAGCTTTGCCTACGGTGCACTGGCTCAGGAGAAAGGACGGACTGGCGATGAAAATATTCATCTGGCTGCGCAGAGCGGGGAAGATCATGTCTGGGCTGAAACGGACGATTCCAGCGCTGGCTCTTCGCCGATTGTCATGGATCCGTGGTCAAACGGTCCTGCCGTTTTTGCAGAGGATAGTCGGTTTGCCAAAGACAGGAGCGGGGTAGAGCGAACGGATTCGTTCACGCTTTCAACGGCAGCCGAAGCAGGCAAGATTACCCGAGAGACAGCCGAGAAGGCGCTGATACAGGCAACCAGCCGTTTGCAGCAACGTCTTGCTGATCAGCAGGCGCAAGTCTCGCCGGTTGAGGGTAGTCGCTATCGGCAAGAAAACTCGGTGCTTGATGATGCGTTCGCCCGACGAGTCAGTGATACGTTGAACAATGCCGATCCACGGCGTGCATTGCAGGTGGAAATCGAGGCGTGCGGAGTCGCAATGTCGCTGGGTGCCCGAGGCGTCAAGACGGTCGTCCAACAGGCGCCAAAGGTGATCAGGCAAGCCAGAAGCGTCGCGTCTCCTAAAGGTATGTCTCCGCGAGCAACTTGA | L6: GCGGCCGCAGTTACCTGGAGTAGTGTTGGCCGTTCGCCTGAGTGAACATCTGTCTGGAACCAACTTGCGCGCAAAACCACACAGTTGCCATCCCTCACCACTTGGATGGCAACCATGAGAATTCACAGTTCTGGTCATGGCATCTGCGCACCAGTGTCCTCTGCAGAAACCGTTGAAAAGGCCGTGCAATCATCGGCCCAAGCGCAGAATGAAGCGTCTCACAGCGGTCCATCAGAACATCCTGAATCCCGCTCCTGTCAGGCACGCCCGAACTACCCTTATTCGTCAGTCAAAACACGGTTACCCCCTGTTGCGTCTGCAGGGCAGTCGTCGTCTGAGACACCCTCTTCATTGCCTGGCTACCTGCTGTTACGTCGGCTTGATCGTCGTCAGCTGGACCAGGACGCAATAAAGGGGCTTATTCCTGCTGATGAAGCAGTGGGCGAAGCGCGCCGCGCGTTGCCCTTCGGCAGGGGCAATATTGATGTGGATGCGCAACGCACCCATCTGCAAAGCGGAGCCCGCACACTCGCGGCAAGGCGCCTGAGAAAAGACGCCGAGGCGGCGGGTCATGAGCCGATGCCCGAGAACGAAGACATGAACTGGCATGTGCTGGTTGCCATGTCGGGTCAGGTGTTCGGTGCGGGCAACTGTGGCGAACATGCGCGTATAGCGAGCTTTGCCTACGGTGCACTGGCTCAGGAGAAAGGACGGACTGGCGATGAAAATATTCATCTGGCTGCGCAGAGCGGGGAAGATCATGTCTGGGCTGAAACGGACGATTCCAGCGCTGGCTCTTCGCCGATTGTCATGGACCCGTGGTCAAACGGTCCTGCCGTTTTTGCAGAGGATAGTCGGTTTGCCAAAGACAGGAGCGGGGTAGAGCGAACGGATTCGTTCACGCTTTCAACGGCAGCCGAAGCAGGCAAGATTACCCGAGAGACAGCCGAGAAGGCGCTGATACAGGCAACCAGCCGTTTGCAGCAACGTCTTGCTGATCAGCAGGCGCAAGTCTCGCCGGTTGAGGGTAGTCGCTATCGGCAAGAAAACTCGGTGCTTGATGATGCGTTCGCCCGACGAGTCAGTGATACGTTGAACAATGCCGATCCACGGCGTGCATTGCAGGTGGAAATCGAGGCGTGCGGAGTCGCAATGTCGCTGGGTGCCCGAGGCGTCAAGACGGTCGTCCAACAGGCGCCAAAGGTGATCAGGCAAGCCAGAAGCGTCGCGTCTCCTAAAGGTATGTCTCCGCGAGCAACTGGCGCATACCCTTACGATGTTCCTGATTACGCATGAGCGAGGGTCAGCCCGCCTAATGAGCGGGCTTTTTTTTGCGCGTAGCAGATGATGACAAGTCGCGGCCGC | M6: GCGAGGGT | N6: =LEN(L6) -> 1365 | O6: =LEN(K6) -> 1149 | P6: MRIHSSGHGICAPVSSAETVEKAVQSSAQAQNEASHSGPSEHPESRSCQARPNYPYSSVKTRLPPVASAGQSSSETPSSLPGYLLLRRLDRRQLDQDAIKGLIPADEAVGEARRALPFGRGNIDVDAQRTHLQSGARTLAARRLRKDAEAAGHEPMPENEDMNWHVLVAMSGQVFGAGNCGEHARIASFAYGALAQEKGRTGDENIHLAAQSGEDHVWAETDDSSAGSSPIVMDPWSNGPAVFAEDSRFAKDRSGVERTDSFTLSTAAEAGKITRETAEKALIQATSRLQQRLADQQAQVSPVEGSRYRQENSVLDDAFARRVSDTLNNADPRRALQVEIEACGVAMSLGARGVKTVVQQAPKVIRQARSVASPKGMSPRAT* | Q6: =(O6-3)/3 -> 382 | R6: 40.92333 | S6: 1 | T6: 0 | U6: 1 | V6: 0
A7: 6 | B7: HopX1d | C7: HopX | D7: HopX1 | E7: 14 | F7: PsaICMP18803_HopX1d_1 | J7: GGAACCAACTCGCACCTTCAACCACACA | K7: ATGAAAATACATAACGCTGGCCCAAGCATTCCGATGCCCGCGCCATCGACTGAGAGCGCTGGCAAGACTGCGCAATCATCATTGACTCAACCGCAGACCCCGGTCTCGCCATCAGAGACCTCTGATGGCCGTCCGTCCAGTGTGCGTACGAACTACCCTTATTCATCAGTCAAAACACGGTTGCCTCCCGTTGCGTCTGCAAGGCAGCCACTGTCCGGGATGCCGTCTTCATTACCCGGCTACTTGCTGTTACGTCGGCTTGACCGTCGTCCACTGGATCAAGACGGTATCAAAGGTTTGATTCCAGCAGATGAAGCGGTGGGTGAAGCACGTCGCGCGTTGCCTTTCGGCAGAGGCAATATCGACGTAGATGCGCAACGCTCCAACCTGGAAAGCGGAGCCCGCACAGTCGCGGCAAGGCGCTTGAGAAAAGATGCCGAGGCCGCGGGTCATGAACCTATGCCTGCAAATGAAGATATGAACTGGCATGTTCTTGTTGCCATGTCAGGACAGGTTTTTGGCGCAGGTAACTGCGGGGAACATGCCCGCATAGCGAGCTTCGCCTATGGTGCACTGGCTCAGGAAAAAGGGCGGAACGCTGATGAATATATTCATTTGGCTGCGCAAAGCGGGGAAGATCATGTCTGGGCTGAGACGGACAATTCAAGCGCTGGATCTTCACCGATTGTCATGGATCCGTGGTCGAACGGTCCTGCCATTTTTGCGGAGGATAGTCGGTTTGCCAAAGATCGAAGTACGGTAGAACGAACGGATTCATTCACGCTTGCAACTGCTGCTGAAGCAGGCAAGATCACGCGAGAGACGGCCGAGAATGCTTTGATACAGGCGACCAGCCGTTTGCAGAAACGTCTTGCTGATCAGAAATCGCAAGTCTCACCGGTTGCAGGGGGGCGATATCGGCAAGAAAATTCGGTGCTTGATGACGCGTTCGCCCGACGAGTAAGTGACACGTTGAACAATGGCGATCCACGGCGTGCATTGCAGGTGGAAATCGAGGCGGCCGGAGTTGCAATGTCGCTGGGCGCCCAAGGCGTAAAAGCGGTTGCGGAACAGGCCCGGACGGTAGTTGAACAAGCCAGGAAGGTCGCATCTCGCAAAGGCACGCCTCAGCGAGATACGTGA | L7: GCGGCCGCAGTTACCTGGAGTAGTGTTGGCATGGCGATCTCGATCATTTTTTCTGGAACCAACTCGCACCTTCAACCACACAGTTGCCATCCCTCACTCTCGGATGGCAACTCACCATGAAAATACATAACGCTGGCCCAAGCATTCCGATGCCCGCGCCATCGACTGAGAGCGCTGGCAAGACTGCGCAATCATCATTGACTCAACCGCAGACCCCGGTCTCGCCATCAGAGACCTCTGATGGCCGTCCGTCCAGTGTGCGTACGAACTACCCTTATTCATCAGTCAAAACACGGTTGCCTCCCGTTGCGTCTGCAAGGCAGCCACTGTCCGGGATGCCGTCTTCATTACCCGGCTACTTGCTGTTACGTCGGCTTGACCGTCGTCCACTGGATCAAGACGGTATCAAAGGTTTGATTCCAGCAGATGAAGCGGTGGGTGAAGCACGTCGCGCGTTGCCTTTCGGCAGAGGCAATATCGACGTAGATGCGCAACGCTCCAACCTGGAAAGCGGAGCCCGCACAGTCGCGGCAAGGCGCTTGAGAAAAGATGCCGAGGCCGCGGGTCATGAACCTATGCCTGCAAATGAAGATATGAACTGGCATGTTCTTGTTGCCATGTCAGGACAGGTTTTTGGCGCAGGTAACTGCGGGGAACATGCCCGCATAGCGAGCTTCGCCTATGGTGCACTGGCTCAGGAAAAAGGGCGGAACGCTGATGAATATATTCATTTGGCTGCGCAAAGCGGGGAAGATCATGTCTGGGCTGAGACGGACAATTCAAGCGCTGGATCTTCACCGATTGTCATGGACCCGTGGTCGAACGGTCCTGCCATTTTTGCGGAGGATAGTCGGTTTGCCAAAGATCGAAGTACGGTAGAACGAACGGATTCATTCACGCTTGCAACTGCTGCTGAAGCAGGCAAGATCACGCGAGAGACGGCCGAGAATGCTTTGATACAGGCGACCAGCCGTTTGCAGAAACGTCTTGCTGATCAGAAATCGCAAGTCTCACCGGTTGCAGGGGGGCGATATCGGCAAGAAAATTCGGTGCTTGATGACGCGTTCGCCCGACGAGTAAGTGACACGTTGAACAATGGCGATCCACGGCGTGCATTGCAGGTGGAAATCGAGGCGGCCGGAGTTGCAATGTCGCTGGGCGCCCAAGGCGTAAAAGCGGTTGCGGAACAGGCCCGGACGGTAGTTGAACAAGCCAGGAAGGTCGCATCTCGCAAAGGCACGCCTCAGCGAGATACGGGCGCATACCCTTACGATGTTCCTGATTACGCATGACTGCAACGCAGCCCGCCTAATGAGCGGGCTTTTTTTTGCGCGTAGCAGATGATGACAAGTCGCGGCCGC | M7: CTGCAACG | N7: =LEN(L7) -> 1361 | O7: =LEN(K7) -> 1143 | P7: MKIHNAGPSIPMPAPSTESAGKTAQSSLTQPQTPVSPSETSDGRPSSVRTNYPYSSVKTRLPPVASARQPLSGMPSSLPGYLLLRRLDRRPLDQDGIKGLIPADEAVGEARRALPFGRGNIDVDAQRSNLESGARTVAARRLRKDAEAAGHEPMPANEDMNWHVLVAMSGQVFGAGNCGEHARIASFAYGALAQEKGRNADEYIHLAAQSGEDHVWAETDNSSAGSSPIVMDPWSNGPAIFAEDSRFAKDRSTVERTDSFTLATAAEAGKITRETAENALIQATSRLQKRLADQKSQVSPVAGGRYRQENSVLDDAFARRVSDTLNNGDPRRALQVEIEAAGVAMSLGAQGVKAVAEQARTVVEQARKVASRKGTPQRDT* | Q7: =(O7-3)/3 -> 380 | R7: 40.60217 | S7: 1 | T7: 1 | U7: 1 | V7: 1 | W7: ZAR1
A8: 7 | B8: HopX1g | C8: HopX | D8: HopX1 | E8: 8 | F8: PalBS91_HopX1g_1 | J8: GGAACCAACTCACGCCCGAAACCACACA | K8: ATGCTCGACCGGAGATTGATGATGAAACCTGTCAGCGGTTCATTTTCTGGCTATCACCCAATGGCGACGGTCAGCGAGCAGCCCGTGGCCAAACCTCGAGCGTCTGAAAGTCCTCAATCCGAAAGCATTGAGGAGCGTCCTGCTTGCCTTGCGCCAGTTGCCGGGGCGGGGCAACCACTGCCCGGCGCATCTTCATCATTGTCTGCCTATTTGCTGCTTCGTAGGCTGGACCACCGTCCAGTGAGTCAGGAGGGTATAAACGCACTCACTCCTGCAGATGAAGCTGTGGTTGAGGCACGAAACGCCTTGCCTTTCGGAAGGGGTAACGTTGGCGTTGATGCGCAAAAGACTGACCTGGAAAGCAGCATACGTACACGTTCTGTGATGCGGCTGACGCGTGACGCCGAGGCTGCAGGTCATACACCCATGCGCGGCGTGGACGCAGACATGAACTGGAATGTGCTCGTCGCGATGTCGGGCCGGATTTTTGGTGCGGGTAACTGCCGCGAACATGCGCGTATCGCCAGCTTCGCTTATGGGGGGCTGGCTCAGGAAAGCGGACGGTCTTCCGAGGAAAAAATTCACCTCGCCACAAAAGCCGGAGTAGATCACGTCTGGGTTGAAACGGACCATCCTGACGCCGACTCTTCACCCATGGTTATTGATCCGTGGGCAAACGGCTCGGCGATTCTCGCAGAAGACAGCCGGTTCGCGAAAGATCGCAGTGCTGTCACTCGCACCGATACTTTCGATCTGTCACTTGCGGCCGAAGCGGGTCAAATTGCCAAGGCGACCGCCGAAGAGGCATTGGCGCACACGCAAGGTCGATTGCAGCAACGTCTTGCAAGCGAGAGGCCGGATGCGGTTCCGCTTGAAAGCGGTCGTTACCGCGAGGAAGTGTCGGTACTCGATGATACGTTTGCCCGCCGCGTTGGACAAAAGGTGAATACAGCCGACCCCAGAGGTATGCTGAATGTCGAGCTTGAAGCCGTTGGGGTTGCGATGTCGCTCGGCGGCGAGGGTGTTAAGCCGCTTACTCAGGAGGCGAGCCAGATTGTCGAGAAGGCGAAGAAGTTTGCATCGCCAGGCGGCATGTCGCGTGATGCGTGA | L8: GCGGCCGCAGTTACCTGGAGTAGTGTTGGCCGTTCGCCTGAATGGGGGTATGTCTGGAACCAACTCACGCCCGAAACCACACAGTTGCCATCCTTCACCACTTGGATGGCAACCATGCTCGACCGGAGATTGATGATGAAACCTGTCAGCGGTTCATTTTCTGGCTATCACCCAATGGCGACGGTCAGCGAGCAGCCCGTGGCCAAACCTCGAGCGTCTGAAAGTCCTCAATCCGAAAGCATTGAGGAGCGTCCTGCTTGCCTTGCGCCAGTTGCCGGGGCGGGGCAACCACTGCCCGGCGCATCTTCATCATTGTCTGCCTATTTGCTGCTTCGTAGGCTGGACCACCGTCCAGTGAGTCAGGAGGGTATAAACGCACTCACTCCTGCAGATGAAGCTGTGGTTGAGGCACGAAACGCCTTGCCTTTCGGAAGGGGTAACGTTGGCGTTGATGCGCAAAAGACTGACCTGGAAAGCAGCATACGTACACGTTCTGTGATGCGGCTGACGCGTGACGCCGAGGCTGCAGGTCATACACCCATGCGCGGCGTGGACGCAGACATGAACTGGAATGTGCTCGTCGCGATGTCGGGCCGGATTTTTGGTGCGGGTAACTGCCGCGAACATGCGCGTATCGCCAGCTTCGCTTATGGGGGGCTGGCTCAGGAAAGCGGACGGTCTTCCGAGGAAAAAATTCACCTCGCCACAAAAGCCGGAGTAGATCACGTCTGGGTTGAAACGGACCATCCTGACGCCGACTCTTCACCCATGGTTATTGATCCGTGGGCAAACGGCTCGGCGATTCTCGCAGAAGACAGCCGGTTCGCGAAAGATCGCAGTGCTGTCACTCGCACCGATACTTTCGATCTGTCACTTGCGGCCGAAGCGGGTCAAATTGCCAAGGCGACCGCCGAAGAGGCATTGGCGCACACGCAAGGTCGATTGCAGCAACGTCTTGCAAGCGAGAGGCCGGATGCGGTTCCGCTTGAAAGCGGTCGTTACCGCGAGGAAGTGTCGGTACTCGATGATACGTTTGCCCGCCGCGTTGGACAAAAGGTGAATACAGCCGACCCCAGAGGTATGCTGAATGTCGAGCTTGAAGCCGTTGGGGTTGCGATGTCGCTCGGCGGCGAGGGTGTTAAGCCGCTTACTCAGGAGGCGAGCCAGATTGTCGAGAAGGCGAAGAAGTTTGCATCGCCAGGCGGCATGTCGCGTGATGCGGGCGCATACCCTTACGATGTTCCTGATTACGCATGAGTATTACACAGCCCGCCTAATGAGCGGGCTTTTTTTTGCGCGTAGCAGATGATGACAAGTCGCGGCCGC | M8: GTATTACA | N8: =LEN(L8) -> 1326 | O8: =LEN(K8) -> 1110 | P8: MLDRRLMMKPVSGSFSGYHPMATVSEQPVAKPRASESPQSESIEERPACLAPVAGAGQPLPGASSSLSAYLLLRRLDHRPVSQEGINALTPADEAVVEARNALPFGRGNVGVDAQKTDLESSIRTRSVMRLTRDAEAAGHTPMRGVDADMNWNVLVAMSGRIFGAGNCREHARIASFAYGGLAQESGRSSEEKIHLATKAGVDHVWVETDHPDADSSPMVIDPWANGSAILAEDSRFAKDRSAVTRTDTFDLSLAAEAGQIAKATAEEALAHTQGRLQQRLASERPDAVPLESGRYREEVSVLDDTFARRVGQKVNTADPRGMLNVELEAVGVAMSLGGEGVKPLTQEASQIVEKAKKFASPGGMSRDA* | Q8: =(O8-3)/3 -> 369 | R8: 39.37816 | S8: 1 | T8: 0 | U8: 1 | V8: 0
A9: 8 | B9: HopF4a | C9: HopF | D9: HopF4 | E9: 43 | F9: PpdICMP8902_HopF4a_1 | J9: GGAACTTCAATAGGGTGTCGTACCACTCA | K9: GTGTATCAACTTTCCGCTGAGGCACGAGATGATTTTCTTGATCGCTTTGACCAAATGCGAAACCTAGGTCTGAACTCGCATGACTCAGCCCATGAGTGGCAGGGCGTATTTTCAACCGATAGAAAGCAACTCGGCGCCTATCTTCTTGCACGCTGTCTTGATGGTCGAGAAGTGAGCGATTCACACGCACAATCACTTGCAGAGGCTAGTGAAACGCTGAAGGATACACGTGACGCGCTCTCTTTCGGTCGTGGAAATGTTGATGCGGATCTAGAGCTAACGCAAGGCGAAAGTGGACAGCGTGTCGCCGCCAGCCGTGTCGTAAATCAACGTTTGAAGGAAAGCGGCGCCAAACTCGGGACCTCGCATACGGTGGCAATGGCCGAATTGGTGAAAGCAGGCTTATGCTCCGAACACGGCGATGTTGCTGTCCATCGCCATATCCCCAAGTTGAAAACCGGTGAGCAGATCCACAAGATCGCAGCCCCTCGCTCCGACCACGGATGGGCTGAACTACGCAGACCAGGCTCACCCAAAGAGAACGCTATCGTCATTGATGCTTGGGCGGAAGGCGGCCCCATCCTTGCGGAGGATGGAAGCTATACCCACCGTCACATTAGCGATGATGCGCGCGTGTCCAGATATGCTTACGGACCTGCTCTGGGACGGCGCGCATTGGCCAGCTTGGAAAAGAGCAGGGCACAGCTGAGCAATATTGCCGTTAGTGTAGAGAGCGCCCGTTCTGAACTGTCTGATAATGGCTACTGGCCTGAATCCGAGCGCATTTGGTCACCGGAGCCGGTCATTGAGAGCGGTTTCGCACAACGTGTCCAAGCGCAGTGCGAGGATAGTAAAAATGCTGAAAGAAACTGGAGCGCCGCGATGAGAATAGCCAGGCAATTAGGGTCTCCTGAAGAGACTCTAGAGAAAAATGCTCGGTCGCTTCTGGAGCTCGCATCCGATTTAAGGCAAGTCCCGCAGAATGCCAGGCGGCCCAACGTTTGA | L9: GCGGCCGCAGTTACCTGGAGTAGTGTTGGCAAATTCCTATACATGAACAGTTGGTGGAACTTCAATAGGGTGTCGTACCACTCAGTTGGCTCAATATCTAAGGGGGCCCCATGAAAAATTCATTCGACCGCTTAATCGATGGGCTCGCAAAAGACTATGGCATGCCTAGTCTTCCTGAGAAGAAACATGAGCACGAAATTTATTGTTTTGAATTTGAGACCGGCGTCTCAATCAAAATTTACCAAGACAAATTTCGCTGGGTGTATTTCGTGGCCGAAATCGGTCAGCTCCACAAAACTAATGCCGATGCGTTGATGAGTATGCTTTATCTCAACAGTTTCAGTTTTAGAAAGCCTTTTTTTACACTGGGTTTGAATAGAAAAAAATTGGAGAGTTACATGCGCGTATCCCTTTGCTGGAGGTTGATAACGTCCAGATGCGAGAGATATTTGAGAATTTACTAGGAGTAGCAGCTGAAATTAAAAAAACGTTCGCTTTTAATTGAGGGGTGTTGTTTATGGTTAATATTTGTGGTACTTCCGGCTCCCATTGTGTATATAGTCCGCCAGTAAGCCCTCGACATGTATCGGGTTCGTCCACACCGGTGCACAGTGTAGGCGGCCAAGGCCTAACCTCGATGTATCAACTTTCCGCTGAGGCACGAGATGATTTTCTTGATCGCTTTGACCAAATGCGAAACCTAGGTCTGAACTCGCATGACTCAGCCCATGAGTGGCAGGGCGTATTTTCAACCGATAGAAAGCAACTCGGCGCCTATCTTCTTGCACGCTGTCTTGATGGTCGAGAAGTGAGCGATTCACACGCACAATCACTTGCAGAGGCTAGTGAAACGCTGAAGGATACACGTGACGCGCTCTCTTTCGGTCGTGGAAATGTTGATGCGGATCTAGAGCTAACGCAAGGCGAAAGTGGACAGCGTGTCGCCGCCAGCCGTGTCGTAAATCAACGTTTGAAGGAAAGCGGCGCCAAACTCGGGACCTCGCATACGGTGGCAATGGCCGAATTGGTGAAAGCAGGCTTATGCTCCGAACACGGCGATGTTGCTGTCCATCGCCATATCCCCAAGTTGAAAACCGGTGAGCAGATCCACAAGATCGCAGCCCCTCGCTCCGACCACGGATGGGCTGAACTACGCAGACCAGGCTCACCCAAAGAGAACGCTATCGTCATTGATGCTTGGGCGGAAGGCGGCCCCATCCTTGCGGAGGATGGAAGCTATACCCACCGTCACATTAGCGATGATGCGCGCGTGTCCAGATATGCTTACGGACCTGCTCTGGGACGGCGCGCATTGGCCAGCTTGGAAAAGAGCAGGGCACAGCTGAGCAATATTGCCGTTAGTGTAGAGAGCGCCCGTTCTGAACTGTCTGATAATGGCTACTGGCCTGAATCCGAGCGCATTTGGTCACCGGAGCCGGTCATTGAGAGCGGTTTCGCACAACGTGTCCAAGCGCAGTGCGAGGATAGTAAAAATGCTGAAAGAAACTGGAGCGCCGCGATGAGAATAGCCAGGCAATTAGGGTCTCCTGAAGAGACTCTAGAGAAAAATGCTCGGTCGCTTCTGGAGCTCGCATCCGATTTAAGGCAAGTCCCGCAGAATGCCAGGCGGCCCAACGTTGGCGCATACCCTTACGATGTTCCTGATTACGCATGATTTATGACCAGCCCGCCTAATGAGCGGGCTTTTTTTTGCGCGTAGCAGATGATGACAAGTCGCGGCCGC | M9: TTTATGAC | N9: =LEN(L9) -> 1744 | O9: =LEN(K9) -> 1005 | P9: VYQLSAEARDDFLDRFDQMRNLGLNSHDSAHEWQGVFSTDRKQLGAYLLARCLDGREVSDSHAQSLAEASETLKDTRDALSFGRGNVDADLELTQGESGQRVAASRVVNQRLKESGAKLGTSHTVAMAELVKAGLCSEHGDVAVHRHIPKLKTGEQIHKIAAPRSDHGWAELRRPGSPKENAIVIDAWAEGGPILAEDGSYTHRHISDDARVSRYAYGPALGRRALASLEKSRAQLSNIAVSVESARSELSDNGYWPESERIWSPEPVIESGFAQRVQAQCEDSKNAERNWSAAMRIARQLGSPEETLEKNARSLLELASDLRQVPQNARRPNV* | Q9: =(O9-3)/3 -> 334 | R9: 36.79176 | S9: 1 | T9: 0 | U9: 1 | V9: 0
A10: 10 | B10: HopBO1c | C10: HopBO | D10: HopBO1 | E10: 18 | F10: PsaICMP18803_HopBO1(P)c_1 | J10: GGAACCGAATCCGTCACAAAGGCCACACA | K10: ATGGGTTCGTGCGTATCAAAAGGGAGCATAGCAAGCTCACCTCAGCATTATGCGGTCCACTACACAGAGCAGGCCACGCCTTCCCCGCCATCCTCCGAGGCGTCCATGTCACCCGGCCCGCGTGACTTGGCAGCTCTGGAGCCTCCCATAGCGAGGCGGTCTGGCGCCAGGCGCTCGGTCCTACTGCCGCACGAAGTTCAACAGGCGGCCTACCAACTCGCTATGCGCCTCAACGGCAGACCCATCGAAGACGCGAGCGCCCGTCAACGCCTTGCCGACGCCACGGCGACGGTGCACGAAACACGACTCGCATTGCACCGTGGAAGAGGCAATGTCGATAGCGATCTGCGGCTCAGCAACGGGCGGGCCGCCACCTATAGTTCTCTGTCCTATTGCCTCGGTGAAGATGATGAAAATTTACTGGCAGGCAGCGCACTGGCTGCCGGGGCAGGCAACTGTGACCACAACGCAGCGATTAACACTCGTCGGCATGCGGTCCGCATGGAGGATGGCGGTCAGATGATGACCGTACGTGACTATGAACAGACCCACCTTTACGCGCTGTACCAACCGCCAAGCTCGACAGATGCGGAGGAATCTACTGTCGTCCTTGACTCATGGGGCGACGGTCCAGCCGTTCTACTAAGGGATTCGCACTGGGCCGAAACGTACGGAACGTCCACTAATATAATTGAGCGATTCGACAAGCCCGCCGCAATAGACTCGCTGGCGAGGACAAATGCATTCAGGGCAGAGATAGAGGACCCGCAAACTGCTCTCCATGCGAATGCGCGCGAACTGGAGACAGCCTTTCTGGCCAACCCCGCACCTGGCGACATATTTTCAGCGATGCCGGTCATCGCTCCCGATCTGGCTGAAAGCACACGCCGCAGGCTGCAAGAGCACTCACCGCGGACGCTTAAGGCTCTAGCCGCCGATGCTGCGCGAAATGCCTATGGGTTGGAGGACGCGCAGGCCAACTCGCCGCGCACGACGAAAGCGATCCTGAAAGAAGCAAAGCGTCTGGACGCCTTGGGTCGCCCGCCCTTGAGTTGGTGA | L10: GCGGCCGCAGTTACCTGGAGTAGTGTTGGCGGGCCATCCGGGCCCACGCTTGCATGGAACCGAATCCGTCACAAAGGCCACACAGTGCGACCATTTTAATGAAATTTTGGTGGCCGCATAACTTCAGCGTCAGCGGTCGAAAACCTTTATTTAAAAGCAGCAGTGCCAACGCCAATCAGAGAGCCTCTCCCTGACGTTGATCACGCAGTACTGCAGGAGTTAAAAAATGGGTTCGTGCGTATCAAAAGGGAGCATAGCAAGCTCACCTCAGCATTATGCGGTCCACTACACAGAGCAGGCCACGCCTTCCCCGCCATCCTCCGAGGCGTCCATGTCACCCGGCCCGCGTGACTTGGCAGCTCTGGAGCCTCCCATAGCGAGGCGGTCTGGCGCCAGGCGCTCGGTCCTACTGCCGCACGAAGTTCAACAGGCGGCCTACCAACTCGCTATGCGCCTCAACGGCAGACCCATCGAAGACGCGAGCGCCCGTCAACGCCTTGCCGACGCCACGGCGACGGTGCACGAAACACGACTCGCATTGCACCGTGGAAGAGGCAATGTCGATAGCGATCTGCGGCTCAGCAACGGGCGGGCCGCCACCTATAGTTCTCTGTCCTATTGCCTCGGTGAAGATGATGAAAATTTACTGGCAGGCAGCGCACTGGCTGCCGGGGCAGGCAACTGTGACCACAACGCAGCGATTAACACTCGTCGGCATGCGGTCCGCATGGAGGATGGCGGTCAGATGATGACCGTACGTGACTATGAACAGACCCACCTTTACGCGCTGTACCAACCGCCAAGCTCGACAGATGCGGAGGAATCTACTGTCGTCCTTGACTCATGGGGCGACGGTCCAGCCGTTCTACTAAGGGATTCGCACTGGGCCGAAACGTACGGAACGTCCACTAATATAATTGAGCGATTCGACAAGCCCGCCGCAATAGACTCGCTGGCGAGGACAAATGCATTCAGGGCAGAGATAGAGGACCCGCAAACTGCTCTCCATGCGAATGCGCGCGAACTGGAGACAGCCTTTCTGGCCAACCCCGCACCTGGCGACATATTTTCAGCGATGCCGGTCATCGCTCCCGATCTGGCTGAAAGCACACGCCGCAGGCTGCAAGAGCACTCACCGCGGACGCTTAAGGCTCTAGCCGCCGATGCTGCGCGAAATGCCTATGGGTTGGAGGACGCGCAGGCCAACTCGCCGCGCACGACGAAAGCGATCCTGAAAGAAGCAAAGCGTCTGGACGCCTTGGGTCGCCCGCCCTTGAGTTGGGGCGCATACCCTTACGATGTTCCTGATTACGCATGAACTAGAGGCAGCCCGCCTAATGAGCGGGCTTTTTTTTGCGCGTAGCAGATGATGACAAGTCGCGGCCGC | M10: ACTAGAGG | N10: =LEN(L10) -> 1387 | O10: =LEN(K10) -> 1059 | P10: MGSCVSKGSIASSPQHYAVHYTEQATPSPPSSEASMSPGPRDLAALEPPIARRSGARRSVLLPHEVQQAAYQLAMRLNGRPIEDASARQRLADATATVHETRLALHRGRGNVDSDLRLSNGRAATYSSLSYCLGEDDENLLAGSALAAGAGNCDHNAAINTRRHAVRMEDGGQMMTVRDYEQTHLYALYQPPSSTDAEESTVVLDSWGDGPAVLLRDSHWAETYGTSTNIIERFDKPAAIDSLARTNAFRAEIEDPQTALHANARELETAFLANPAPGDIFSAMPVIAPDLAESTRRRLQEHSPRTLKALAADAARNAYGLEDAQANSPRTTKAILKEAKRLDALGRPPLSW* | Q10: =(O10-3)/3 -> 352 | R10: 37.99723 | S10: 1 | T10: 0 | U10: 1 | V10: 0
A11: 11 | B11: HopBO1b | C11: HopBO | D11: HopBO1 | E11: 25 | F11: PspICMP16928_HopBO1(P)b_1 | J11: GGAACCGAATCCGTCCCAAAGGCCACATA | K11: ATGGGTTCGTGCGTTTCCAAAGGGAGCACAGCAAGCTCACCTCAGCATTATGCTGTCCAATACACAGAGCAGGCCACGCCTTCCCCTTCATCCTCCGAGGCGTCCATGTCACCCAGCCTGCATGGCTCGACGGCCCTGGAGTCTCCCATTGCGAGGTGGTCTGGTGCCAGGCGCTCGGTCCTACTGCCGCACGAAGTCCAGCAGGCTGCCTACCAACTCGCTATGCGCCTCAACGGCAGGCCCATCGACGCGAGCGACCGTCAACGCCTTGCCGACGCAACGTCTACGGTGCATGAGACACGACTCGCATTGCACCGTGGACGAGGCAATGTCGACAGCGATCTGCGGCTCAGCAACGGACGGAGCGCCACCTATAGTTCCCTGTCCTACTGCCTCGGCGAAGATGACGAAAATTTACTGGCAGGCAGCGCGCTGGCTGCTGGGGCAGGCAACTGTGACCACAACGCAGCGATTAACACACGTCGGCATGCGGTCCGCATGGAGGATGGCGGGCAGATGATGACCGTACGTGACTATGAGCAGACCCACCTCTACGCGCTGTACCAGCCGCCAAACTCGGCAGAAGCGGATGAATCCACTGTAGTCCTTGACTCGTGGGGCGACGGTCCAGCCGTTCTACTGAGGGATTCGCACTGGGCCGAATCGTATGGAACGTCCACCCATGTAATTGAACGATTCGACAAGCCTGATGCAACCGACGCGCTGGCGAGGACAAACGCATTCAGAGCCGAGATCGAGAACCCGCAAACTGCGCTCCATGCGAATGCACGCGAGTTGGAGACAGCCTTTCTCGCCAATCCCGCACCTGGCGACATCTTTTCCGCGATGCCGGTCATCGCTCCCGATCTGGCCGAAAGTACGCGTCGGAGGCTGCAAGAGTACTCACCGCGGACGCGTAATGTTCTAGCCGCCGATGCTGCGCGTGATGCCTACGGGCTGGATGACGCGCATGCCAACTCGCCTCGCACGACGAAAGCGATCCTGAAAGAAGCAAAGCGACTGGATGCCTTGGGTCGCCCGCCCTTGAGTTGGTGA | L11: GCGGCCGCAGTTACCTGGAGTAGTGTTGGCCTTTGGCGTTGGCCCACGTTCGCAAGGAACCGAATCCGTCCCAAAGGCCACATAAACAAAGCTTCAATGAAAATTCGGCATTTGATAATTTCAGCGTCAGCGGTTGAAAACCTTTAAAAGCAGCAGTGAGTGAGCCAACGCCAATTAGAGAGCGTCTCGCTAATGCTGATGACTCAGAACTGCAGGAGTTAGAAAATGGGTTCGTGCGTTTCCAAAGGGAGCACAGCAAGCTCACCTCAGCATTATGCTGTCCAATACACAGAGCAGGCCACGCCTTCCCCTTCATCCTCCGAGGCGTCCATGTCACCCAGCCTGCATGGCTCGACGGCCCTGGAGTCTCCCATTGCGAGGTGGTCTGGTGCCAGGCGCTCGGTCCTACTGCCGCACGAAGTCCAGCAGGCTGCCTACCAACTCGCTATGCGCCTCAACGGCAGGCCCATCGACGCGAGCGACCGTCAACGCCTTGCCGACGCAACGTCTACGGTGCATGAGACACGACTCGCATTGCACCGTGGACGAGGCAATGTCGACAGCGATCTGCGGCTCAGCAACGGACGGAGCGCCACCTATAGTTCCCTGTCCTACTGCCTCGGCGAAGATGACGAAAATTTACTGGCAGGCAGCGCGCTGGCTGCTGGGGCAGGCAACTGTGACCACAACGCAGCGATTAACACACGTCGGCATGCGGTCCGCATGGAGGATGGCGGGCAGATGATGACCGTACGTGACTATGAGCAGACCCACCTCTACGCGCTGTACCAGCCGCCAAACTCGGCAGAAGCGGATGAATCCACTGTAGTCCTTGACTCGTGGGGCGACGGTCCAGCCGTTCTACTGAGGGATTCGCACTGGGCCGAATCGTATGGAACGTCCACCCATGTAATTGAACGATTCGACAAGCCTGATGCAACCGACGCGCTGGCGAGGACAAACGCATTCAGAGCCGAGATCGAGAACCCGCAAACTGCGCTCCATGCGAATGCACGCGAGTTGGAGACAGCCTTTCTCGCCAATCCCGCACCTGGCGACATCTTTTCCGCGATGCCGGTCATCGCTCCCGATCTGGCCGAAAGTACGCGTCGGAGGCTGCAAGAGTACTCACCGCGGACGCGTAATGTTCTAGCCGCCGATGCTGCGCGTGATGCCTACGGGCTGGATGACGCGCATGCCAACTCGCCTCGCACGACGAAAGCGATCCTGAAAGAAGCAAAGCGACTGGATGCCTTGGGTCGCCCGCCCTTGAGTTGGGGCGCATACCCTTACGATGTTCCTGATTACGCATGAACCAAGCTCAGCCCGCCTAATGAGCGGGCTTTTTTTTGCGCGTAGCAGATGATGACAAGTCGCGGCCGC | M11: ACCAAGCT | N11: =LEN(L11) -> 1383 | O11: =LEN(K11) -> 1056 | P11: MGSCVSKGSTASSPQHYAVQYTEQATPSPSSSEASMSPSLHGSTALESPIARWSGARRSVLLPHEVQQAAYQLAMRLNGRPIDASDRQRLADATSTVHETRLALHRGRGNVDSDLRLSNGRSATYSSLSYCLGEDDENLLAGSALAAGAGNCDHNAAINTRRHAVRMEDGGQMMTVRDYEQTHLYALYQPPNSAEADESTVVLDSWGDGPAVLLRDSHWAESYGTSTHVIERFDKPDATDALARTNAFRAEIENPQTALHANARELETAFLANPAPGDIFSAMPVIAPDLAESTRRRLQEYSPRTRNVLAADAARDAYGLDDAHANSPRTTKAILKEAKRLDALGRPPLSW* | Q11: =(O11-3)/3 -> 351 | R11: 37.99191 | S11: 1 | T11: 0 | U11: 1 | V11: 0
A12: 12 | B12: HopBO1a | C12: HopBO | D12: HopBO1 | E12: 34 | F12: PbrICMP13685_HopBO1(P)a_1 | J12: GGAACCGAATCCGTCCCAAAGGCCACATA | K12: ATGGGTTCGTGCGTTTCCAAAGGGAGCACAGCAAGCTCACCTCAGCATTATGCTGTCCAATACACAGAGCAGGCCACGCCTTCCTCTTCATCCTCCGAGGCGTCCATGTCACCCAGCCTGCATGGCTCGACGGCCCTGGAGTCTCCCATTGCGAGGTGGTCTGGTGCCAGGCGCTCGGTCCTACTGCCGCACGAAGTCCAGCAGGCTGCCTACCAACTCGCTATGCGCCTCAACGGCAGGCCCATCGACGCGAGCGACCGTCAACGCCTTGCCGACGCCACGGCGACGATGCACGAGACACGACTCGCATTGCACCGTGGTCGGGGCAATGTTGTTAGCGATCTGCGGCTAAGCAACGTACGGAGCGCCACCTACAGCTCCCTCTCCTACTCTCTCGGTGAAAATGACGAAAATTTACTGGCAGGCAGCGCACTGGCTGCCGGGGCAGGCAACTGTGACCACAACGCAGCGATTAACACACGTCGGCACGCGGACCGTATGGAGGATGGCGGGCAGATGATGACCGTACGTGACTATGAGCATTCCCACCTCTACGCGCTGTACCAGCCGCCTAACTCGGCAGAAGCGGAAGAATCTGTAGTCCTTGACTCGTGGGCCGACGGCCCGGCCGTTCTACTAAGGGATTCGCACTGGGCCGAAACGTACGGAACGTCCAATGTAACTGAACGATTCGACAAGTCTGACGCAATCGACGCGCTGGCAAGGGCAAACGCATTCAGAGCCGAGGTTGAGGACCCGCAAACTGCGCTCCATGCAAATGCGCGCGAGTTGGAGACAGTCTTTCTGGCCAACCCCGCACCTGGCGACATCCGTACCGCAATGCCGATTATCGCTCCCCATCTGGCCGAAAACACGCGTCGGAGGCTGGAAGAGTACTCACCGCGGACGCGTACTGTTCTAGCCGCCGATGCTGCGCGGGATGCCTACGGGCTGGAAGACTCGCGTGCCAACTCGCCGCGCACGACGAAAGCGATCCTGAAAGACGCAACACGACTGGATGCCTTGGGTCGCCCGCCCTTGAGTTGGTGA | L12: GCGGCCGCAGTTACCTGGAGTAGTGTTGGCTAGTTGCGTTGGCCCACATTTGCAAGGAACCGAATCCGTCCCAAAGGCCACATAAAAAAATTTTCAATGAAAATTCGGCATTTGCATAATTTCAGCGTCAGCGGTTGAAAACCTTTAAAAACAGCAGTGAGTGAGCCAACGCCAATTAGAGAGCGTCTCGCTAATGCTGATGACTCAGAACTGCAGGAGTTAAAAAATGGGTTCGTGCGTTTCCAAAGGGAGCACAGCAAGCTCACCTCAGCATTATGCTGTCCAATACACAGAGCAGGCCACGCCTTCCTCTTCATCCTCCGAGGCGTCCATGTCACCCAGCCTGCATGGCTCGACGGCCCTGGAGTCTCCCATTGCGAGGTGGTCTGGTGCCAGGCGCTCGGTCCTACTGCCGCACGAAGTCCAGCAGGCTGCCTACCAACTCGCTATGCGCCTCAACGGCAGGCCCATCGACGCGAGCGACCGTCAACGCCTTGCCGACGCCACGGCGACGATGCACGAGACACGACTCGCATTGCACCGTGGTCGGGGCAATGTTGTTAGCGATCTGCGGCTAAGCAACGTACGGAGCGCCACCTACAGCTCCCTCTCCTACTCTCTCGGTGAAAATGACGAAAATTTACTGGCAGGCAGCGCACTGGCTGCCGGGGCAGGCAACTGTGACCACAACGCAGCGATTAACACACGTCGGCACGCGGACCGTATGGAGGATGGCGGGCAGATGATGACCGTACGTGACTATGAGCATTCCCACCTCTACGCGCTGTACCAGCCGCCTAACTCGGCAGAAGCGGAAGAATCTGTAGTCCTTGACTCGTGGGCCGACGGCCCGGCCGTTCTACTAAGGGATTCGCACTGGGCCGAAACGTACGGAACGTCCAATGTAACTGAACGATTCGACAAGTCTGACGCAATCGACGCGCTGGCAAGGGCAAACGCATTCAGAGCCGAGGTTGAGGACCCGCAAACTGCGCTCCATGCAAATGCGCGCGAGTTGGAGACAGTCTTTCTGGCCAACCCCGCACCTGGCGACATCCGTACCGCAATGCCGATTATCGCTCCCCATCTGGCCGAAAACACGCGTCGGAGGCTGGAAGAGTACTCACCGCGGACGCGTACTGTTCTAGCCGCCGATGCTGCGCGGGATGCCTACGGGCTGGAAGACTCGCGTGCCAACTCGCCGCGCACGACGAAAGCGATCCTGAAAGACGCAACACGACTGGATGCCTTGGGTCGCCCGCCCTTGAGTTGGGGCGCATACCCTTACGATGTTCCTGATTACGCATGAACCAAGTCCAGCCCGCCTAATGAGCGGGCTTTTTTTTGCGCGTAGCAGATGATGACAAGTCGCGGCCGC | M12: ACCAAGTC | N12: =LEN(L12) -> 1378 | O12: =LEN(K12) -> 1050 | P12: MGSCVSKGSTASSPQHYAVQYTEQATPSSSSSEASMSPSLHGSTALESPIARWSGARRSVLLPHEVQQAAYQLAMRLNGRPIDASDRQRLADATATMHETRLALHRGRGNVVSDLRLSNVRSATYSSLSYSLGENDENLLAGSALAAGAGNCDHNAAINTRRHADRMEDGGQMMTVRDYEHSHLYALYQPPNSAEAEESVVLDSWADGPAVLLRDSHWAETYGTSNVTERFDKSDAIDALARANAFRAEVEDPQTALHANARELETVFLANPAPGDIRTAMPIIAPHLAENTRRRLEEYSPRTRTVLAADAARDAYGLEDSRANSPRTTKAILKDATRLDALGRPPLSW* | Q12: =(O12-3)/3 -> 349 | R12: 37.89184 | S12: 1 | T12: 0 | U12: 1 | V12: 0
A13: 13 | B13: HopBO1d | C13: HopBO | D13: HopBO1 | E13: 15 | F13: PalPSa1_3_HopBO1(P)d_1 | J13: GGAACCGAATCCTCCCCAAAGGCCACACA | K13: ATGGGTTTGTGCGTTTCAAAAGGTAGCACAGCAAGCTCGCCTCAGCATTATGCGGTCCGATACACAGAGCAGGTCACGCCTTCCCCTTCACCTTCCGTGGCGTCCACGTCACCCAGTCTGCACGATTCGACGGCCATAGGGTCTCCCCTGGCGAGGCGTTCTGTCCTACTTCCGCACGAAGTTCAGCAGGCGGCCTACCAACTCGCTATGCGCCTCAACGGCAGGGCCATCGAAGACGCGAGCGACCGTAAACGCCTTGTCGACGCCACGGCGACGGTGCACGAGACACGACTCGCATTGCACCGTGGACGAGGCAAGGTCGACAGCGATCTGCGGCTCAGCAATGGACGGAGCGCTACCTATAGTTCCCTATCTTACTGCCTCGGCGAAGATGACGAAAATTTACTGGCAGGCAGCGCGCTGGCTGCCGGGGCAGGCAACTGTGACCACAACGCAGCGATTAACACACGTCGGCATGCGGTCCGCATGGAGGATGGCGGCCAGATGATGACCGTACGTGACTATGAGCAGACCCACCTCTACGCGCTGTACCAGCCGCCAAACTCGGCAGAAGCGGACGAATCCACTGTAGTCCTTGACTCGTGGGGCGACGGTCCAGCCGTTCTACTGAGGGATTCGCACTGGGCCGAATCGTATGGAACGTCCACCCACGTAATTGAACGATTCGACAAGCCTGATGCAACCGACGCGCTGGCGAGGACTAACGCATTCAGAGCCGAGATCGAGAACCCTCAAACTGCGCTCCATGCGAATGCGCGCGAGTTGGAGACAGCCTTTCTCGCCAATCCCGCACCTGGCGACATCTTTTCCGCTATGCCGGTCATCGCTCCCCATCTGGCCGAAAGCACGCGTCGGAGGCTGCAAGAGTGCTCACCACGGACGCGTAATGTTCTAGCCGCCGATGCTGCGCGTGATGCCTACGGGCTGGATGACGCGCAGGCCAACTCGCCGCGCACTACGAAAGCGATCCTGAAAGAAGCAAAGCGACTGGATGCCTTGGGTCGCCCGCCCTTGAGTTGGTGA | L13: GCGGCCGCAGTTACCTGGAGTAGTGTTGGCTGTTGTTTGGTCCAGGTATTTATATGGAACCGAATCCTCCCCAAAGGCCACACAGCACGAGCAATCCAACGAAAATTTGGCGGCTGAATAACGTCAGCGTCAGCGTTTGAAAACTTTTAAAAGCAGATGTGAGCCAACGCCAATCAAAGAACGTTGCTAAAGTTGATGACTTAGTACTGCAGGAGTTAAAAAATGGGTTTGTGCGTTTCAAAAGGTAGCACAGCAAGCTCGCCTCAGCATTATGCGGTCCGATACACAGAGCAGGTCACGCCTTCCCCTTCACCTTCCGTGGCGTCCACGTCACCCAGTCTGCACGATTCGACGGCCATAGGGTCTCCCCTGGCGAGGCGTTCTGTCCTACTTCCGCACGAAGTTCAGCAGGCGGCCTACCAACTCGCTATGCGCCTCAACGGCAGGGCCATCGAAGACGCGAGCGACCGTAAACGCCTTGTCGACGCCACGGCGACGGTGCACGAGACACGACTCGCATTGCACCGTGGACGAGGCAAGGTCGACAGCGATCTGCGGCTCAGCAATGGACGGAGCGCTACCTATAGTTCCCTATCTTACTGCCTCGGCGAAGATGACGAAAATTTACTGGCAGGCAGCGCGCTGGCTGCCGGGGCAGGCAACTGTGACCACAACGCAGCGATTAACACACGTCGGCATGCGGTCCGCATGGAGGATGGCGGCCAGATGATGACCGTACGTGACTATGAGCAGACCCACCTCTACGCGCTGTACCAGCCGCCAAACTCGGCAGAAGCGGACGAATCCACTGTAGTCCTTGACTCGTGGGGCGACGGTCCAGCCGTTCTACTGAGGGATTCGCACTGGGCCGAATCGTATGGAACGTCCACCCACGTAATTGAACGATTCGACAAGCCTGATGCAACCGACGCGCTGGCGAGGACTAACGCATTCAGAGCCGAGATCGAGAACCCTCAAACTGCGCTCCATGCGAATGCGCGCGAGTTGGAGACAGCCTTTCTCGCCAATCCCGCACCTGGCGACATCTTTTCCGCTATGCCGGTCATCGCTCCCCATCTGGCCGAAAGCACGCGTCGGAGGCTGCAAGAGTGCTCACCACGGACGCGTAATGTTCTAGCCGCCGATGCTGCGCGTGATGCCTACGGGCTGGATGACGCGCAGGCCAACTCGCCGCGCACTACGAAAGCGATCCTGAAAGAAGCAAAGCGACTGGATGCCTTGGGTCGCCCGCCCTTGAGTTGGGGCGCATACCCTTACGATGTTCCTGATTACGCATGAGCACCGTACAGCCCGCCTAATGAGCGGGCTTTTTTTTGCGCGTAGCAGATGATGACAAGTCGCGGCCGC | M13: GCACCGTA | N13: =LEN(L13) -> 1368 | O13: =LEN(K13) -> 1044 | P13: MGLCVSKGSTASSPQHYAVRYTEQVTPSPSPSVASTSPSLHDSTAIGSPLARRSVLLPHEVQQAAYQLAMRLNGRAIEDASDRKRLVDATATVHETRLALHRGRGKVDSDLRLSNGRSATYSSLSYCLGEDDENLLAGSALAAGAGNCDHNAAINTRRHAVRMEDGGQMMTVRDYEQTHLYALYQPPNSAEADESTVVLDSWGDGPAVLLRDSHWAESYGTSTHVIERFDKPDATDALARTNAFRAEIENPQTALHANARELETAFLANPAPGDIFSAMPVIAPHLAESTRRRLQECSPRTRNVLAADAARDAYGLDDAQANSPRTTKAILKEAKRLDALGRPPLSW* | Q13: =(O13-3)/3 -> 347 | R13: 37.53468 | S13: 1 | T13: 0 | U13: 1 | V13: 0
A14: 18 | B14: AvrRpm1a | C14: AvrRpm | D14: AvrRpm1 | E14: 76 | F14: PsaCFBP7286_AvrRpm1a_1 | J14: GGAACTCATTAGCTTTCGAATGCCACAGA | K14: ATGGGCTGTGTATCGAGTACGTCAAGAAGCACTGGATATTATTCTGGTTACGAAAGCCATGAGGAACCCAGGGCGGCAAGCAGACCGACGAACAGCGATGATCGCGGCTACGAAACTGATTCAGAGCCATCCAGTGGCAACTTGATACCCAATGCGAGGAGAGTGTATAGCGAATCTGTTTTGTGGCACGGTACATCCATGCAATCAAAAATAGACTTGAGAAGCAAAGGGTTCGATGCAGGTAGAAAAACTGGCGGCGCTACTGCAGGTGGCAACGCAAATATGTTTATGAACTTGAGTAGGGAGGCTCAGTCTGAATCCAGACAACATCATTATTTGTCTTCATCCCGAAAAGAAGCCAAGGACTTTGCCATTTTTGCTGACATGAGTAATCCCACACTGGTACGCACTATCGGCGTCAGAAACAACTTAAGCCTGATAACCGACCCCAGAACCGGCGGCACCGCACTCATGACAGATCAATCGATTCCGCGCAAATTTGTGCTCGGATCAAAAAGCAGTGCTCCCGGAGAAAATGCGAAAGTCTTCAGGGATGAAATGCGTGCGGCAGGACACAATGTGTCGACAAAGCAAGCCGGCGAACTGCTCAGAGAAGTCCAGTCTGATTCAGACGATGACAACTTCCCTGACCCCGATGACTTTATCATGAGCCGCTTTACTGGATAA | L14: GCGGCCGCAGTTACCTGGAGTAGTGTTGGCCAGCGCAATGGGTCGACTCTGACAGGGAACTCATTAGCTTTCGAATGCCACAGATCAGTTCCATACTTTCAAGCAAGAGGTCTTTTATGGGCTGTGTATCGAGTACGTCAAGAAGCACTGGATATTATTCTGGTTACGAAAGCCATGAGGAACCCAGGGCGGCAAGCAGACCGACGAACAGCGATGATCGCGGCTACGAAACTGATTCAGAGCCATCCAGTGGCAACTTGATACCCAATGCGAGGAGAGTGTATAGCGAATCTGTTTTGTGGCACGGTACATCCATGCAATCAAAAATAGACTTGAGAAGCAAAGGGTTCGATGCAGGTAGAAAAACTGGCGGCGCTACTGCAGGTGGCAACGCAAATATGTTTATGAACTTGAGTAGGGAGGCTCAGTCTGAATCCAGACAACATCATTATTTGTCTTCATCCCGAAAAGAAGCCAAGGACTTTGCCATTTTTGCTGACATGAGTAATCCCACACTGGTACGCACTATCGGCGTCAGAAACAACTTAAGCCTGATAACCGACCCCAGAACCGGCGGCACCGCACTCATGACAGATCAATCGATTCCGCGCAAATTTGTGCTCGGATCAAAAAGCAGTGCTCCCGGAGAAAATGCGAAAGTCTTCAGGGATGAAATGCGTGCGGCAGGACACAATGTGTCGACAAAGCAAGCCGGCGAACTGCTCAGAGAAGTCCAGTCTGATTCAGACGATGACAACTTCCCTGACCCCGATGACTTTATCATGAGCCGCTTTACTGGAGGCGCATACCCTTACGATGTTCCTGATTACGCATAAGCACAATGCAGCCCGCCTAATGAGCGGGCTTTTTTTTGCGCGTAGCAGATGATGACAAGTCGCGGCCGC | M14: GCACAATG | N14: =LEN(L14) -> 905 | O14: =LEN(K14) -> 687 | P14: MGCVSSTSRSTGYYSGYESHEEPRAASRPTNSDDRGYETDSEPSSGNLIPNARRVYSESVLWHGTSMQSKIDLRSKGFDAGRKTGGATAGGNANMFMNLSREAQSESRQHHYLSSSRKEAKDFAIFADMSNPTLVRTIGVRNNLSLITDPRTGGTALMTDQSIPRKFVLGSKSSAPGENAKVFRDEMRAAGHNVSTKQAGELLREVQSDSDDDNFPDPDDFIMSRFTG* | Q14: =(O14-3)/3 -> 228 | R14: 24.90627 | S14: 1 | T14: 0 | U14: 1 | V14: 0
A15: 19 | B15: AvrRpm1h | C15: AvrRpm | D15: AvrRpm1 | E15: 3 | F15: PthICMP3923_AvrRpm1h_1 | J15: GGAACTCATTTGCTGTTTGATGCCACAGA | K15: ATGGGCTGTGTATCGAGTACATCAAGAAGCACTGGCTATTACTCCGGCTACGAAAGCCATGAGGAACCCAGGGCGGCAAGCAGAACCGCAAACAGCAATGAGCGCGGCTACGAAACCGATTCCGAGCCATCCCGCGACAACTTGTTACCCAATGCCAAGAGAGTGTATAGCGAGTCTGTTTTGTGGCACGGCACGTCCATGCAATCAAAAATAGACTTGAGAAGCAAAGGGTTTGATGCGGATAGAAAAAAAGGCGGCGCTACAGAAGGTGGCAACGCCAATATGTTTATGAACCTGAGCAGTGAGGCTCAGGCGGAATCCAGACAGAATCACTATGTGTCGTCCTCCCGAAAGGAAGCCAAGGACTTTGCCATGTTCGCTGACATGAGTAATCCCGGACTGGTACGCACCATCGGCCTCAGAAGCAACTTCAATCTGATATCCGACCCCAGGACCGGCGGCACTGCGCTCATGACAGATCAGTCGATTCATCGGAAGTTTGTGCTCGGATCAAAAAGCAGTGCTCCCGGAGAAAACGCAAAGGTCTTCAGGGATGAAATGCATGCAGCGGGGTACGATGTATCGACGAAGCAAGCCGGCAAGCTGCTTAGAGAAGTCCAGTCTGATTCAGATGATGACAACTTCCCGGACCCCGATGACTTTATCATGAGCCGATTCAGGGGCTGA | L15: GCGGCCGCAGTTACCTGGAGTAGTGTTGGCCTTTAGCCTGACAGAAGCCAAGCTGGGAACTCATTTGCTGTTTGATGCCACAGATAACGTCCATACGTTCAATCAAAAGGTTTTTTATGGGCTGTGTATCGAGTACATCAAGAAGCACTGGCTATTACTCCGGCTACGAAAGCCATGAGGAACCCAGGGCGGCAAGCAGAACCGCAAACAGCAATGAGCGCGGCTACGAAACCGATTCCGAGCCATCCCGCGACAACTTGTTACCCAATGCCAAGAGAGTGTATAGCGAGTCTGTTTTGTGGCACGGCACGTCCATGCAATCAAAAATAGACTTGAGAAGCAAAGGGTTTGATGCGGATAGAAAAAAAGGCGGCGCTACAGAAGGTGGCAACGCCAATATGTTTATGAACCTGAGCAGTGAGGCTCAGGCGGAATCCAGACAGAATCACTATGTGTCGTCCTCCCGAAAGGAAGCCAAGGACTTTGCCATGTTCGCTGACATGAGTAATCCCGGACTGGTACGCACCATCGGCCTCAGAAGCAACTTCAATCTGATATCCGACCCCAGGACCGGCGGCACTGCGCTCATGACAGATCAGTCGATTCATCGGAAGTTTGTGCTCGGATCAAAAAGCAGTGCTCCCGGAGAAAACGCAAAGGTCTTCAGGGATGAAATGCATGCAGCGGGGTACGATGTATCGACGAAGCAAGCCGGCAAGCTGCTTAGAGAAGTCCAGTCTGATTCAGATGATGACAACTTCCCGGACCCCGATGACTTTATCATGAGCCGATTCAGGGGCGGCGCATACCCTTACGATGTTCCTGATTACGCATGAAATATCGTCAGCCCGCCTAATGAGCGGGCTTTTTTTTGCGCGTAGCAGATGATGACAAGTCGCGGCCGC | M15: AATATCGT | N15: =LEN(L15) -> 905 | O15: =LEN(K15) -> 687 | P15: MGCVSSTSRSTGYYSGYESHEEPRAASRTANSNERGYETDSEPSRDNLLPNAKRVYSESVLWHGTSMQSKIDLRSKGFDADRKKGGATEGGNANMFMNLSSEAQAESRQNHYVSSSRKEAKDFAMFADMSNPGLVRTIGLRSNFNLISDPRTGGTALMTDQSIHRKFVLGSKSSAPGENAKVFRDEMHAAGYDVSTKQAGKLLREVQSDSDDDNFPDPDDFIMSRFRG* | Q15: =(O15-3)/3 -> 228 | R15: 25.12351 | S15: 1 | T15: 0 | U15: 1 | V15: 0
A16: 20 | B16: AvrRpm1d | C16: AvrRpm | D16: AvrRpm1 | E16: 13 | F16: PfiICMP7848_AvrRpm1d_1 | J16: GGAACTCATTTTCTTTTAAAACCACACA | K16: ATGGGCTGTGTATCGAGCACTTCAAGAAGTACTGGATATTATTCCGGTTACGAAAGTCATGATGAGCCAAGGGTGGCAAGTAGCCCGGCAAACAGGCATGATCGCGGCTACGAAACCGATTCCGAGCATTCCAATGACAACTTAATACCCAATGCGAGGAGAGTGTATAAAGAGTCTGTTTTGTGGCATGGTACATCTATGCAATCAAAAATAGATTTGAGAAGGCAAGGGTTTGATGTGAATAGAAAAACTGATGGTGCAACCGAGGGATCTAGAACATCGAACTCAGCCCCTACAGACACGCTCATCAGAAATGCTAGACGTCACAACTACTTAACAGCTTATGATGTAACAGCTAAGAATTATGCTCGAAGAGCAGACCCCGAATCCCCAGCCCTAGTTAGAACTATAGGTGTCAAGAGTAATTTTAATATTGAGCTAGATCCTGAATCGAAAGACGAGAATGGTGAAATATCCCAATTCAGCTGTAGAACGACAGATTCAATACCTAAAAAATACATTGTTGGAAGCAAGAGCAGCCAGCCGGGAGCGGATGCAAAGGTTTTTAAAACAGAACTCTCCAATGCGGGTTTTGAAGTTTCCACAAGCCGTGCAGGCGAGTTATTAAGAGCTGTTCAGTCTGACTCAGAAGATGACTTTTAA | L16: GCGGCCGCAGTTACCTGGAGTAGTGTTGGCCGCCCAGTGGAGTCTGTTCCAGCAGGGAACTCATTTTCTTTTAAAACCACACATGTACTCCATACCTTCAATCAAAAGGTTTTTTATGGGCTGTGTATCGAGCACTTCAAGAAGTACTGGATATTATTCCGGTTACGAAAGTCATGATGAGCCAAGGGTGGCAAGTAGCCCGGCAAACAGGCATGATCGCGGCTACGAAACCGATTCCGAGCATTCCAATGACAACTTAATACCCAATGCGAGGAGAGTGTATAAAGAGTCTGTTTTGTGGCATGGTACATCTATGCAATCAAAAATAGATTTGAGAAGGCAAGGGTTTGATGTGAATAGAAAAACTGATGGTGCAACCGAGGGATCTAGAACATCGAACTCAGCCCCTACAGACACGCTCATCAGAAATGCTAGACGTCACAACTACTTAACAGCTTATGATGTAACAGCTAAGAATTATGCTCGAAGAGCAGACCCCGAATCCCCAGCCCTAGTTAGAACTATAGGTGTCAAGAGTAATTTTAATATTGAGCTAGATCCTGAATCGAAAGACGAGAATGGTGAAATATCCCAATTCAGCTGTAGAACGACAGATTCAATACCTAAAAAATACATTGTTGGAAGCAAGAGCAGCCAGCCGGGAGCGGATGCAAAGGTTTTTAAAACAGAACTCTCCAATGCGGGTTTTGAAGTTTCCACAAGCCGTGCAGGCGAGTTATTAAGAGCTGTTCAGTCTGACTCAGAAGATGACTTTGGCGCATACCCTTACGATGTTCCTGATTACGCATAATTCAGTGCCAGCCCGCCTAATGAGCGGGCTTTTTTTTGCGCGTAGCAGATGATGACAAGTCGCGGCCGC | M16: TTCAGTGC | N16: =LEN(L16) -> 880 | O16: =LEN(K16) -> 663 | P16: MGCVSSTSRSTGYYSGYESHDEPRVASSPANRHDRGYETDSEHSNDNLIPNARRVYKESVLWHGTSMQSKIDLRRQGFDVNRKTDGATEGSRTSNSAPTDTLIRNARRHNYLTAYDVTAKNYARRADPESPALVRTIGVKSNFNIELDPESKDENGEISQFSCRTTDSIPKKYIVGSKSSQPGADAKVFKTELSNAGFEVSTSRAGELLRAVQSDSEDDF* | Q16: =(O16-3)/3 -> 220 | R16: 24.37149 | S16: 1 | T16: 1 | U16: 1 | V16: 1 | W16: RPM1
A17: 21 | B17: AvrRpm1e | C17: AvrRpm | D17: AvrRpm1 | E17: 12 | F17: PneICMP13781_AvrRpm1e_1 | J17: GGAACCAAATATGTAGTTATGGTCACTCA | K17: ATGGGTAATATATGTGGTACTTCTGGCTCCCATCATGTGTATAGTCCGCCAGTTAGCCCTCGAAATGTCTCTGGTTCGTCAACACCAGAATACAGTGCAGGTGGCCAAGCCCTAACGTCAGCATCTCATCTTTCTGGAGGGGCACGAGAAGATTTTCTCACGCGTGCTGCAGCGGACGTATATAAAAATAGTCGGCTCTGGCACGGCACTTCGGGGAGCTATTTGCAAGAACTCAGAGATAATGGGTTTCAGCTTCAGCGGAGGCGTTCAGGTGCTGTAGACGCTACGCTCCGAGCCGGCTACGAATTAAACCCGGATGTCGTGAAAAATACGGAAAAGCATAATTATTTTACTAGTTATCCGGTATCTGCAAAAAAATATGCTCGTCGGACAGATCCAGATAACCCCGTTCTCGTTAGAACTATAGGGATAAAAAACAACTTTCCAATTGAGCTGGATCCTGACAGCAAAGGCCCAGACGGAGAAATTTTTCCGTATAATTGTAGGACAACCTCATCCATTCCTTCAAAGTTTGTAGTTGGATCTAAACATAGCTCGCCCAAAAATGATGCCAAAGTTTTTAAAAAGGAAATGGGTGAAGCGGGCTATAATGTCTCTCTCGAGCAAGCGGGACGATTACTGCGGGAAGTGCAGTCAGATTCTGACGACGACTTCTGA | L17: GCGGCCGCAGTTACCTGGAGTAGTGTTGGCTCCGCGGCTTCCAAAAAAATCGATGGAACCAAATATGTAGTTATGGTCACTCACCTGACTTAAAAGGTAGAGGTACTTCATGGGTAATATATGTGGTACTTCTGGCTCCCATCATGTGTATAGTCCGCCAGTTAGCCCTCGAAATGTCTCTGGTTCGTCAACACCAGAATACAGTGCAGGTGGCCAAGCCCTAACGTCAGCATCTCATCTTTCTGGAGGGGCACGAGAAGATTTTCTCACGCGTGCTGCAGCGGACGTATATAAAAATAGTCGGCTCTGGCACGGCACTTCGGGGAGCTATTTGCAAGAACTCAGAGATAATGGGTTTCAGCTTCAGCGGAGGCGTTCAGGTGCTGTAGACGCTACGCTCCGAGCCGGCTACGAATTAAACCCGGATGTCGTGAAAAATACGGAAAAGCATAATTATTTTACAAGTTATCCGGTATCTGCAAAAAAATATGCTCGTCGGACAGATCCAGATAACCCCGTTCTCGTTAGAACTATAGGGATAAAAAACAACTTTCCAATTGAGCTGGACCCTGACAGCAAAGGCCCAGACGGAGAAATTTTTCCGTATAATTGTAGGACAACCTCATCCATTCCTTCAAAGTTTGTAGTTGGATCTAAACATAGCTCGCCCAAAAATGATGCCAAAGTTTTTAAAAAGGAAATGGGTGAAGCGGGCTATAATGTCTCTCTCGAGCAAGCGGGACGATTACTGCGGGAAGTGCAGTCAGATTCTGACGACGACTTCGGCGCATACCCTTACGATGTTCCTGATTACGCATGAAGCCTTATCAGCCCGCCTAATGAGCGGGCTTTTTTTTGCGCGTAGCAGATGATGACAAGTCGCGGCCGC | M17: AGCCTTAT | N17: =LEN(L17) -> 889 | O17: =LEN(K17) -> 678 | P17: MGNICGTSGSHHVYSPPVSPRNVSGSSTPEYSAGGQALTSASHLSGGAREDFLTRAAADVYKNSRLWHGTSGSYLQELRDNGFQLQRRRSGAVDATLRAGYELNPDVVKNTEKHNYFTSYPVSAKKYARRTDPDNPVLVRTIGIKNNFPIELDPDSKGPDGEIFPYNCRTTSSIPSKFVVGSKHSSPKNDAKVFKKEMGEAGYNVSLEQAGRLLREVQSDSDDDF* | Q17: =(O17-3)/3 -> 225 | R17: 24.59412 | S17: 1 | T17: 0 | U17: 0 | V17: 0
A18: 22 | B18: AvrRpm1f | C18: AvrRpm | D18: AvrRpm1 | E18: 7 | F18: PneICMP13786_AvrRpm1f_1 | J18: GGAACCAAATATGTAGTTATGGTCACTCA | K18: GTGGGTAATATTTGTGGTACTTCTGGCTCCCATCATGTGTATAGTCCGCCAGTTAGCCCTCGAAATGTTTCTGGTTCATCAACACCAGCATACAGTGCAGGTGGCCAAGACCTAGCCTCAGCATCTCATCTTTCCGAAGAGGCACGAGAAGATTTTCTTACGCGTGCTGCAGCGGACGTATATCACGATAGTAGGCTCTGGCACGGAACTTCGGGGAGCTATTTGCAAGAACTCAGAGATTATGGGTTTCAGCGGAGGCGTTCAGGTGCTGTAGACGCTTCTATCCGAGCCGGCTACGAATTAAACCCGGATGTCGTGAAAAATACGGAAAAGCATAATTATTTTACTAGTTATCCGGTATCTGCAAAAAAATATGCTCGTCGGACAGATCCAGATAACCCCGTTCTCGTTAGAACTATAGGGATAAAAAACAACTTTCGAATTGAGCTGGATCCTGACAGCAAAGGCCCTGACGGAGAAATTTATCAGTATAATTGTAGGACAACCTCATCCATTCCGTCAAAGTTTGTAATTGGATCAAAACATAGCGCACCCAAAAATGATGCCAAAATTTTTAAAAAGGAAATGGGTGAAGCAGGCTATAATGTCTCTCTCGAGCAAGCGGGACGATTACTGCGGGAAGTGCAGTCAGATTCTGACGACGACTTCTGA | L18: GCGGCCGCAGTTACCTGGAGTAGTGTTGGCTCCCCGGCCCCCAAAAAATTTCGATGGAACCAAATATGTAGTTATGGTCACTCACCTGACTTAAAGGTAGAGGTAGAGGTATTTCATGGGTAATATTTGTGGTACTTCTGGCTCCCATCATGTGTATAGTCCGCCAGTTAGCCCTCGAAATGTTTCTGGTTCATCAACACCAGCATACAGTGCAGGTGGCCAAGACCTAGCCTCAGCATCTCATCTTTCCGAAGAGGCACGAGAAGATTTTCTTACGCGTGCTGCAGCGGACGTATATCACGATAGTAGGCTCTGGCACGGAACTTCGGGGAGCTATTTGCAAGAACTCAGAGATTATGGGTTTCAGCGGAGGCGTTCAGGTGCTGTAGACGCTTCTATCCGAGCCGGCTACGAATTAAACCCGGATGTCGTGAAAAATACGGAAAAGCATAATTATTTTACAAGTTATCCGGTATCTGCAAAAAAATATGCTCGTCGGACAGATCCAGATAACCCCGTTCTCGTTAGAACTATAGGGATAAAAAACAACTTTCGAATTGAGCTGGACCCTGACAGCAAAGGCCCTGACGGAGAAATTTATCAGTATAATTGTAGGACAACCTCATCCATTCCGTCAAAGTTTGTAATTGGATCAAAACATAGCGCACCCAAAAATGATGCCAAAATTTTTAAAAAGGAAATGGGTGAAGCAGGCTATAATGTCTCTCTCGAGCAAGCGGGACGATTACTGCGGGAAGTGCAGTCAGATTCTGACGACGACTTCGGCGCATACCCTTACGATGTTCCTGATTACGCATGAGCCGAATTCAGCCCGCCTAATGAGCGGGCTTTTTTTTGCGCGTAGCAGATGATGACAAGTCGCGGCCGC | M18: GCCGAATT | N18: =LEN(L18) -> 889 | O18: =LEN(K18) -> 672 | P18: VGNICGTSGSHHVYSPPVSPRNVSGSSTPAYSAGGQDLASASHLSEEAREDFLTRAAADVYHDSRLWHGTSGSYLQELRDYGFQRRRSGAVDASIRAGYELNPDVVKNTEKHNYFTSYPVSAKKYARRTDPDNPVLVRTIGIKNNFRIELDPDSKGPDGEIYQYNCRTTSSIPSKFVIGSKHSAPKNDAKIFKKEMGEAGYNVSLEQAGRLLREVQSDSDDDF* | Q18: =(O18-3)/3 -> 223 | R18: 24.58398 | S18: 1 | T18: 0 | U18: 1 | V18: 0
A19: 23 | B19: AvrRpm1i | C19: AvrRpm | D19: AvrRpm1 | E19: 2 | F19: PmaH7608_AvrRpm1i_1 | J19: GGAACCAAATATGTAGTTATGGTCACTCA | K19: ATGGGTAATATATGTGGTACTTCTGGCTCCCATCATGTGTATAGTCCGCCAGTTAGCCCTCGAAATGTCTCTGGTTCGTCAACACCAGAATACAGTGCAGGCGGCCAAGCCCTAACGTCAGCATCCCATCTTTCTGGAGGGGCACGAGAAGATTTTCTCACGCGTGCTGCAGCGGACGTATATAAAAATAGTCGGCTCTGGCACGGAACTTCAGGGAGCTATTTGGAAGAACTCAGAGATTACGGGTTTCAGCGGAGGCGTTCAGGTGCTGTAGACGCCACTCTCCGCGCCGGCTACGAATTGAACCCGGCTGTTGTGAAAAACACGGAGAAGCATAATTATTTTACTAGTTATCCGGTAACTGCAAAAAACTATGCTCGTCGGACAGATCCAGACAATCCCGTTCTTGTGCGGACCATCGGGTTGAGGAACAACTTTTCCCTCGAGCTAGATCCAGACAGTAAAGGCCCGGACGGAGAGATTTCCAAATATAGTTGTAGGACAACCTCATCCATTCCTTCAAAGTTTGTAGTTGGATCAAAACATAGCGCGCCCAAGGATGATGCCAAAGTTTTTAAAGAGGAAATGGGTGAGGCAGGCTATAATGTCTCTCGCGAGCAAGCGGGACGATTACTGCGGGAAGTGCAGTCAGATTCTGACGACGATTTCTGA | L19: GCGGCCGCAGTTACCTGGAGTAGTGTTGGCTCCGCGGCTTCCAAAAAAATCGATGGAACCAAATATGTAGTTATGGTCACTCACCTGACTTAAAGGTAGAGGTACTTCAATGGGTAATATATGTGGTACTTCTGGCTCCCATCATGTGTATAGTCCGCCAGTTAGCCCTCGAAATGTCTCTGGTTCGTCAACACCAGAATACAGTGCAGGCGGCCAAGCCCTAACGTCAGCATCCCATCTTTCTGGAGGGGCACGAGAAGATTTTCTCACGCGTGCTGCAGCGGACGTATATAAAAATAGTCGGCTCTGGCACGGAACTTCAGGGAGCTATTTGGAAGAACTCAGAGATTACGGGTTTCAGCGGAGGCGTTCAGGTGCTGTAGACGCCACTCTCCGCGCCGGCTACGAATTGAACCCGGCTGTTGTGAAAAACACGGAGAAGCATAATTATTTTACAAGTTATCCGGTAACTGCAAAAAACTATGCTCGTCGGACAGATCCAGACAATCCCGTTCTTGTGCGGACCATCGGGTTGAGGAACAACTTTTCCCTCGAGCTAGATCCAGACAGTAAAGGCCCGGACGGAGAGATTTCCAAATATAGTTGTAGGACAACCTCATCCATTCCTTCAAAGTTTGTAGTTGGATCAAAACATAGCGCGCCCAAGGATGATGCCAAAGTTTTTAAAGAGGAAATGGGTGAGGCAGGCTATAATGTCTCTCGCGAGCAAGCGGGACGATTACTGCGGGAAGTGCAGTCAGATTCTGACGACGATTTCGGCGCATACCCTTACGATGTTCCTGATTACGCATGATAGCCAACCAGCCCGCCTAATGAGCGGGCTTTTTTTTGCGCGTAGCAGATGATGACAAGTCGCGGCCGC | M19: TAGCCAAC | N19: =LEN(L19) -> 883 | O19: =LEN(K19) -> 672 | P19: MGNICGTSGSHHVYSPPVSPRNVSGSSTPEYSAGGQALTSASHLSGGAREDFLTRAAADVYKNSRLWHGTSGSYLEELRDYGFQRRRSGAVDATLRAGYELNPAVVKNTEKHNYFTSYPVTAKNYARRTDPDNPVLVRTIGLRNNFSLELDPDSKGPDGEISKYSCRTTSSIPSKFVVGSKHSAPKDDAKVFKEEMGEAGYNVSREQAGRLLREVQSDSDDDF* | Q19: =(O19-3)/3 -> 223 | R19: 24.3497 | S19: 1 | T19: 0 | U19: 1 | V19: 0
A20: 46 | B20: HopO1h | C20: HopO | D20: HopO1 | E20: 2 | F20: PavICMP9749_HopO1h_1 | J20: GGAACGGTCTCGCGGCAAGTCTTACGGA | K20: ATGAATATCAACCCTTCCCAAGGCACCTATGGCAGTGCCTACTCGTCGTCCCAAAATGATACATCGAAGGCCACTGGAAAAGCCCCTGCGCCCTCTTTGCTCAAACAGTTGGGCAGCTGTTTCTCGCCATGCCTTGGTTCTCAAGCCTCAAGCAGCCAACACCTGTCCGCCAGTCATGCGCAAACGCTCAGTCAGAATTACTCCAGCAACATTCCAGAGGGGACGAGCCGCACACGCCAGCCGAGAGCGCCCTCGCCACGCCTGTCAGATACGCCCATGAAGCAGGCGCTTTCCTCAATGATCGGACGCGAGCGTTTGCGGCTTCAAGGTCTTTCGGGAGGAATGTTCTCGGGCATTGACTCCGCCGATGCCATGATTGGTCGAGCGCTCACGAAGAAGGATTCAAACCCAAAGGCTGCGCGTTTTAGTGATGATGAGTTTCTCGCCATTCACCTCTACACAACTTGCCTCTACAGACCTATCAATCATCATCTTCGGTATCAACACCAGGATGATGTACCTCCGATTGTGGAGGCCCTGAAGAGTGGTCTCGCCAAGCTTGCCCGCGATCCCGACTATCAAGTAGCTGCCCCGCTTCACCGAGGCATCGAAAAAACCATGTCTGATGAAGAGGTCATGAAGCGTTTCAATTCCGGTAGGCCGTACCGTGATGAAGCGTTCATGAGTACATCGACCGATTCCGTCATTGCGAACAGTTTGACCTCAAGCGTGGCACTGCACCTTCAATCAACCTCTGCGGTCAATGTGAGCCCGTTCGCCATAAATGCCCACGAGAAAGAGGCGATTATCCCGCCTCAAACCCCTTTCGAGGTCGTGGGGCTCAAGAAAATGCACAGTACTTGGCATGTGGATTTGAAAGAAGTTCAGGACAACGCTGACGGGAGTTAG | L20: GCGGCCGCAGTTACCTGGAGTAGTGTTGGCTTCTACCTGGTTTTATTCAAGGCTCGGAACGGTCTCGCGGCAAGTCTTACGGACAAATAAAAGCTTTTTTCCGGCCGGAGCTTTAAGCTCGCGCTTCAAATCGGTCCTCATCACAGACGCTAGGTTTTCATTCCATGAATATCAACCCTTCCCAAGGCACCTATGGCAGTGCCTACTCGTCGTCCCAAAATGATACATCGAAGGCCACTGGAAAAGCCCCTGCGCCCTCTTTGCTCAAACAGTTGGGCAGCTGTTTCTCGCCATGCCTTGGTTCTCAAGCCTCAAGCAGCCAACACCTGTCCGCCAGTCATGCGCAAACGCTCAGTCAGAATTACTCCAGCAACATTCCAGAGGGGACGAGCCGCACACGCCAGCCGAGAGCGCCCTCGCCACGCCTGTCAGATACGCCCATGAAGCAGGCGCTTTCCTCAATGATCGGACGCGAGCGTTTGCGGCTTCAAGGTCTTTCGGGAGGAATGTTCTCGGGCATTGACTCCGCCGATGCCATGATTGGTCGAGCGCTCACGAAGAAGGATTCAAACCCAAAGGCTGCGCGTTTTAGTGATGATGAGTTTCTCGCCATTCACCTCTACACAACTTGCCTCTACAGACCTATCAATCATCATCTTCGGTATCAACACCAGGATGATGTACCTCCGATTGTGGAGGCCCTGAAGAGTGGTCTCGCCAAGCTTGCCCGCGATCCCGACTATCAAGTAGCTGCCCCGCTTCACCGAGGCATCGAAAAAACCATGTCTGATGAAGAGGTCATGAAGCGTTTCAATTCCGGTAGGCCGTACCGTGATGAAGCGTTCATGAGTACATCGACCGATTCCGTCATTGCGAACAGTTTGACCTCAAGCGTGGCACTGCACCTTCAATCAACCTCTGCGGTCAATGTGAGCCCGTTCGCCATAAATGCCCACGAGAAAGAGGCGATTATCCCGCCTCAAACCCCTTTCGAGGTCGTGGGGCTCAAGAAAATGCACAGTACTTGGCATGTGGATTTGAAAGAAGTTCAGGACAACGCTGACGGGAGTGGCGCATACCCTTACGATGTTCCTGATTACGCATAGTCGGGATACAGCCCGCCTAATGAGCGGGCTTTTTTTTGCGCGTAGCAGATGATGACAAGTCGCGGCCGC | M20: TCGGGATA | N20: =LEN(L20) -> 1175 | O20: =LEN(K20) -> 909 | P20: MNINPSQGTYGSAYSSSQNDTSKATGKAPAPSLLKQLGSCFSPCLGSQASSSQHLSASHAQTLSQNYSSNIPEGTSRTRQPRAPSPRLSDTPMKQALSSMIGRERLRLQGLSGGMFSGIDSADAMIGRALTKKDSNPKAARFSDDEFLAIHLYTTCLYRPINHHLRYQHQDDVPPIVEALKSGLAKLARDPDYQVAAPLHRGIEKTMSDEEVMKRFNSGRPYRDEAFMSTSTDSVIANSLTSSVALHLQSTSAVNVSPFAINAHEKEAIIPPQTPFEVVGLKKMHSTWHVDLKEVQDNADGS* | Q20: =(O20-3)/3 -> 302 | R20: 32.80073 | S20: 1 | T20: 0 | U20: 1 | V20: 0
A21: 51 | B21: HopU1a | C21: HopU | D21: HopU1 | E21: 15 | F21: Pap1089_5_HopU1a_1 | J21: GGAACCTGATGCTGCTCAGTGACCACTCA | K21: ATGAATATAAATCGACAACTGCCTGTATCAGGCTCGGAGCGATTGTTGACTCCCGACGTGGGCGTATCTCGCCAGGCTTGTTCCGAAAGGCATTATTCTACTGGACAGGATCGGCATGATTTTTACCGTTTTGCTGCCAGGCTACATGTGGATGCGCAGTGTTTTGGTCTGTCAATAGACGATTTGATGGATAAGTTTTCTGACAAGCACTTCAGGGCTGAGCATCCTGAATACAGGGATGTCTATCCGGAGGAATGTTCTGCCATTTATATGCATACCGCTCAAGACTATTCTAGTCACCTCGTAAGGGGGGAAATAGGAACGCCGCTGTACCGAGAGGTCAATAATTATCTTCGACTTCAACATGAGAATTCTGGGCGAGAAGCTGAAATTGATAATCACGACGAAAAGCTATCGCCTCACATAAAAATGCTTTCATCTGCGCTTAATCGTTTAATGGATGTCGCCGCTTTTAGAGGAACGGTTTATAGAGGAATTCGCGGTGATTTAGATACGATTGCTCGGCTCTACCATCTATTCGATACGGGCGGCCGGTACGTAGAGCCCGCTTTCATGAGTACAACTCGAATAAAGGACAGTGCTCAGGTGTTTGAGCCAGGCACGCCAAACAACATAGCTTTCCAGATAAGCCTAAAAAGAGGAGCCGACATTTCGGGATCTTCCCAAGCGCCCTCAGAGGAAGAAATCATGCTACCCATGATGAGTGAGTTCGTCATTGAACATGCATCCGCTCTTTCCGAAGGAAAGCATTTATTTGTATTAAGTCAGATTTGA | L21: GCGGCCGCAGTTACCTGGAGTAGTGTTGGCCTCACTGACGAGCATCATCAAAAAGGGAACCTGATGCTGCTCAGTGACCACTCATAACCTTAAATTATGAGGATATGAGGAGATGCATTAATGAATATAAATCGACAACTGCCTGTATCAGGCTCGGAGCGATTGTTGACTCCCGACGTGGGCGTATCTCGCCAGGCTTGTTCCGAAAGGCATTATTCTACTGGACAGGATCGGCATGATTTTTACCGTTTTGCTGCCAGGCTACATGTGGATGCGCAGTGTTTTGGTCTGTCAATAGACGATTTGATGGATAAGTTTTCTGACAAGCACTTCAGGGCTGAGCATCCTGAATACAGGGATGTCTATCCGGAGGAATGTTCTGCCATTTATATGCATACCGCTCAAGACTATTCTAGTCACCTCGTAAGGGGGGAAATAGGAACGCCGCTGTACCGAGAGGTCAATAATTATCTTCGACTTCAACATGAGAATTCTGGGCGAGAAGCTGAAATTGATAATCACGACGAAAAGCTATCGCCTCACATAAAAATGCTTTCATCTGCGCTTAATCGTTTAATGGATGTCGCCGCTTTTAGAGGAACGGTTTATAGAGGAATTCGCGGTGATTTAGATACGATTGCTCGGCTCTACCATCTATTCGATACGGGCGGCCGGTACGTAGAGCCCGCTTTCATGAGTACAACTCGAATAAAGGACAGTGCTCAGGTGTTTGAGCCAGGCACGCCAAACAACATAGCTTTCCAGATAAGCCTAAAAAGAGGAGCCGACATTTCGGGATCTTCCCAAGCGCCCTCAGAGGAAGAAATCATGCTACCCATGATGAGTGAGTTCGTCATTGAACATGCATCCGCTCTTTCCGAAGGAAAGCATTTATTTGTATTAAGTCAGATTGGCGCATACCCTTACGATGTTCCTGATTACGCATGACTCTGTCGCAGCCCGCCTAATGAGCGGGCTTTTTTTTGCGCGTAGCAGATGATGACAAGTCGCGGCCGC | M21: CTCTGTCG | N21: =LEN(L21) -> 1017 | O21: =LEN(K21) -> 795 | P21: MNINRQLPVSGSERLLTPDVGVSRQACSERHYSTGQDRHDFYRFAARLHVDAQCFGLSIDDLMDKFSDKHFRAEHPEYRDVYPEECSAIYMHTAQDYSSHLVRGEIGTPLYREVNNYLRLQHENSGREAEIDNHDEKLSPHIKMLSSALNRLMDVAAFRGTVYRGIRGDLDTIARLYHLFDTGGRYVEPAFMSTTRIKDSAQVFEPGTPNNIAFQISLKRGADISGSSQAPSEEEIMLPMMSEFVIEHASALSEGKHLFVLSQI* | Q21: =(O21-3)/3 -> 264 | R21: 29.9866 | S21: 1 | T21: 0 | U21: 1 | V21: 0
